Workbook

Sheet JOB
A1: JOB - one job: BOM, freight, labor, other direct costs, price build-up and close-out
A3: Job name | B3: Sample: 5 kWp / 6 kW / 11.7 kWh hybrid
A4: Client
A5: Site address | B5: Pila-area site
A6: Date
A7: Extra km beyond a Pila-area site, one way | B7: 0 | C7: Input. Adds to the truck run and to crew transport each day
A8: Extra toll per round trip for a farther site | B8: 0 | C8: Input
A9: Net metering application? (Yes/No) | B9: Yes
A10: LABOR INPUTS
A11: Roof difficulty factor | B11: ='LABOR RATES'!B63 -> 0.75 | C11: Simple roof by default; 1.00 = your 9.12 kWp multi-face roof; 1.25 two-storey or steep; 1.50 tile
A12: Roof closed within (days) | B12: 1
A13: Max installation days | B13: 2
A14: Max pairs | B14: 2 | C14: Pairs of 1 skilled + 1 laborer on top of team lead + 1 laborer
A15: Battery hauling hours per pack | B15: 0.5 | C15: 0.5 ground floor, short carry; 1.0 or more upstairs or long carry
A16: Your days on site (optional) | B16: 0
A18: TAKEOFF FOR LABOR (worked out from the BOM below; type over a cell if a count is wrong)
A19: Panels | B19: =SUMIF($D$33:$D$72,"Solar Panel",$B$33:$B$72) -> 8
A20: Hybrid inverters (incl. all-in-one) | B20: =SUMPRODUCT($R$33:$R$72,$B$33:$B$72) -> 1
A21: Grid-tie inverters | B21: =SUMIF($D$33:$D$72,"Inverter",$B$33:$B$72)-SUMPRODUCT(($D$33:$D$72="Inverter")*$R$33:$R$72*$B$33:$B$72) -> 0
A22: Battery packs | B22: =SUMIF($D$33:$D$72,"Battery",$B$33:$B$72) -> 1
A23: Heaviest battery pack, kg | B23: =IF(B22=0,0,SUMPRODUCT(MAX(($D$33:$D$72="Battery")*$M$33:$M$72))) -> 111
A24: Enclosures (boxes) | B24: =SUMPRODUCT(($D$33:$D$72="Enclosures and Raceways")*((ISNUMBER(SEARCH("box",$C$33:$C$72))+ISNUMBER(SEARCH("enclosure",$C$33:$C$72)))>0)*$B$33:$B$72) -> 2
A25: Breakers, SPDs, ATS | B25: =SUMIF($D$33:$D$72,"Protective Devices",$B$33:$B$72) -> 13
A26: Conduit and cable tray, m | B26: =SUMPRODUCT(($D$33:$D$72="Enclosures and Raceways")*($F$33:$F$72="m")*$B$33:$B$72)+2*SUMPRODUCT(($D$33:$D$72="Enclosures and Raceways")*ISNUMBER(SEARCH("tray",$C$33:$C$72))*($F$33:$F$72="pc")*$B$33:$B$72) -> 32 | C26: Tray pieces counted as 2 m each; conduit sold by the roll is not counted - type over if needed
A27: Wire, m | B27: =SUMPRODUCT(($D$33:$D$72="Wires and Terminations")*($F$33:$F$72="m")*$B$33:$B$72) -> 65
A28: String home-run MC4 pairs | B28: =SUMPRODUCT(ISNUMBER(SEARCH("MC4",$C$33:$C$72))*$B$33:$B$72) -> 4
A29: Ground rods | B29: =SUMPRODUCT(($D$33:$D$72="Grounding")*ISNUMBER(SEARCH("rod",$C$33:$C$72))*$B$33:$B$72) -> 1
A31: BOM - enter DB codes and quantities (sample: the 6 kW hybrid from your rev2 package)
A32: Code (input) | B32: Qty (input) | C32: Item | D32: Category | E32: Supplier | F32: Unit | G32: Landed cost per unit, before freight | H32: Markup tier | I32: Landed cost, line | J32: Markup, line | K32: Selling price, line | L32: Truck share, line | M32: Weight per unit, kg | N32: Actual cost, line (close-out input) | O32: Variance (actual - estimate) | P32: Remarks | Q32: Rating | R32: Hybrid inverter? (1/0)
A33: BC-PNL-004 | B33: 8 | C33: =IF($A33="","",IFERROR(INDEX('MATERIALS DB'!$D$4:$D$465,MATCH($A33,'MATERIALS DB'!$A$4:$A$465,0)),"Code not found")) -> 630W Bifacial solar panel | D33: =IF($A33="","",IFERROR(INDEX('MATERIALS DB'!$B$4:$B$465,MATCH($A33,'MATERIALS DB'!$A$4:$A$465,0)),"")) -> Solar Panel | E33: =IF($A33="","",IFERROR(INDEX('MATERIALS DB'!$C$4:$C$465,MATCH($A33,'MATERIALS DB'!$A$4:$A$465,0)),"")) -> Blue Carbon | F33: =IF($A33="","",IFERROR(INDEX('MATERIALS DB'!$F$4:$F$465,MATCH($A33,'MATERIALS DB'!$A$4:$A$465,0)),"")) -> pc | G33: =IF($A33="",0,IFERROR(INDEX('MATERIALS DB'!$W$4:$W$465,MATCH($A33,'MATERIALS DB'!$A$4:$A$465,0)),0)) -> 5497.9295 | H33: =IF($A33="",0,IFERROR(INDEX('MATERIALS DB'!$Y$4:$Y$465,MATCH($A33,'MATERIALS DB'!$A$4:$A$465,0)),0)) -> 0.1 | I33: =B33*G33 -> 43983.436 | J33: =I33*H33 -> 4398.3436 | K33: =I33+J33 -> 48381.78 | L33: =IF($A33="",0,IFERROR(B33*INDEX('MATERIALS DB'!$Q$4:$Q$465,MATCH($A33,'MATERIALS DB'!$A$4:$A$465,0))*(INDEX(SUPPLIERS!$F$3:$F$30,MATCH(E33,SUPPLIERS!$A$3:$A$30,0))<>"Yes"),0)) -> 0.073866667 | M33: =IF($A33="",0,IFERROR(INDEX('MATERIALS DB'!$N$4:$N$465,MATCH($A33,'MATERIALS DB'!$A$4:$A$465,0)),0)) -> 27.7 | O33: =IF(N33="","",N33-I33) | Q33: =IF($A33="",0,IFERROR(INDEX('MATERIALS DB'!$K$4:$K$465,MATCH($A33,'MATERIALS DB'!$A$4:$A$465,0)),0)) -> 630 | R33: =IF($A33="",0,IF(OR(D33="All-in-one System",AND(D33="Inverter",OR(ISNUMBER(SEARCH("hybrid",C33)),ISNUMBER(SEARCH("off-grid",C33))))),1,0)) -> 0
A34: FS-INV-001 | B34: 1 | C34: =IF($A34="","",IFERROR(INDEX('MATERIALS DB'!$D$4:$D$465,MATCH($A34,'MATERIALS DB'!$A$4:$A$465,0)),"Code not found")) -> 6 kW low-voltage hybrid inverter (grid-tie + backup) | D34: =IF($A34="","",IFERROR(INDEX('MATERIALS DB'!$B$4:$B$465,MATCH($A34,'MATERIALS DB'!$A$4:$A$465,0)),"")) -> Inverter | E34: =IF($A34="","",IFERROR(INDEX('MATERIALS DB'!$C$4:$C$465,MATCH($A34,'MATERIALS DB'!$A$4:$A$465,0)),"")) -> Felicity Solar | F34: =IF($A34="","",IFERROR(INDEX('MATERIALS DB'!$F$4:$F$465,MATCH($A34,'MATERIALS DB'!$A$4:$A$465,0)),"")) -> pc | G34: =IF($A34="",0,IFERROR(INDEX('MATERIALS DB'!$W$4:$W$465,MATCH($A34,'MATERIALS DB'!$A$4:$A$465,0)),0)) -> 43042.393 | H34: =IF($A34="",0,IFERROR(INDEX('MATERIALS DB'!$Y$4:$Y$465,MATCH($A34,'MATERIALS DB'!$A$4:$A$465,0)),0)) -> 0.1 | I34: =B34*G34 -> 43042.393 | J34: =I34*H34 -> 4304.2393 | K34: =I34+J34 -> 47346.632 | L34: =IF($A34="",0,IFERROR(B34*INDEX('MATERIALS DB'!$Q$4:$Q$465,MATCH($A34,'MATERIALS DB'!$A$4:$A$465,0))*(INDEX(SUPPLIERS!$F$3:$F$30,MATCH(E34,SUPPLIERS!$A$3:$A$30,0))<>"Yes"),0)) -> 0.0081666667 | M34: =IF($A34="",0,IFERROR(INDEX('MATERIALS DB'!$N$4:$N$465,MATCH($A34,'MATERIALS DB'!$A$4:$A$465,0)),0)) -> 24.5 | O34: =IF(N34="","",N34-I34) | Q34: =IF($A34="",0,IFERROR(INDEX('MATERIALS DB'!$K$4:$K$465,MATCH($A34,'MATERIALS DB'!$A$4:$A$465,0)),0)) -> 6 | R34: =IF($A34="",0,IF(OR(D34="All-in-one System",AND(D34="Inverter",OR(ISNUMBER(SEARCH("hybrid",C34)),ISNUMBER(SEARCH("off-grid",C34))))),1,0)) -> 1
A35: FS-BAT-006 | B35: 1 | C35: =IF($A35="","",IFERROR(INDEX('MATERIALS DB'!$D$4:$D$465,MATCH($A35,'MATERIALS DB'!$A$4:$A$465,0)),"Code not found")) -> LiFePO4 51.2V 230Ah (11.7 kWh), FLB IP65 | D35: =IF($A35="","",IFERROR(INDEX('MATERIALS DB'!$B$4:$B$465,MATCH($A35,'MATERIALS DB'!$A$4:$A$465,0)),"")) -> Battery | E35: =IF($A35="","",IFERROR(INDEX('MATERIALS DB'!$C$4:$C$465,MATCH($A35,'MATERIALS DB'!$A$4:$A$465,0)),"")) -> Felicity Solar | F35: =IF($A35="","",IFERROR(INDEX('MATERIALS DB'!$F$4:$F$465,MATCH($A35,'MATERIALS DB'!$A$4:$A$465,0)),"")) -> pc | G35: =IF($A35="",0,IFERROR(INDEX('MATERIALS DB'!$W$4:$W$465,MATCH($A35,'MATERIALS DB'!$A$4:$A$465,0)),0)) -> 87192.064 | H35: =IF($A35="",0,IFERROR(INDEX('MATERIALS DB'!$Y$4:$Y$465,MATCH($A35,'MATERIALS DB'!$A$4:$A$465,0)),0)) -> 0.15 | I35: =B35*G35 -> 87192.064 | J35: =I35*H35 -> 13078.81 | K35: =I35+J35 -> 100270.87 | L35: =IF($A35="",0,IFERROR(B35*INDEX('MATERIALS DB'!$Q$4:$Q$465,MATCH($A35,'MATERIALS DB'!$A$4:$A$465,0))*(INDEX(SUPPLIERS!$F$3:$F$30,MATCH(E35,SUPPLIERS!$A$3:$A$30,0))<>"Yes"),0)) -> 0.037 | M35: =IF($A35="",0,IFERROR(INDEX('MATERIALS DB'!$N$4:$N$465,MATCH($A35,'MATERIALS DB'!$A$4:$A$465,0)),0)) -> 111 | O35: =IF(N35="","",N35-I35) | Q35: =IF($A35="",0,IFERROR(INDEX('MATERIALS DB'!$K$4:$K$465,MATCH($A35,'MATERIALS DB'!$A$4:$A$465,0)),0)) -> 11.7 | R35: =IF($A35="",0,IF(OR(D35="All-in-one System",AND(D35="Inverter",OR(ISNUMBER(SEARCH("hybrid",C35)),ISNUMBER(SEARCH("off-grid",C35))))),1,0)) -> 0
A36: BC-MNT-001 | B36: 8 | C36: =IF($A36="","",IFERROR(INDEX('MATERIALS DB'!$D$4:$D$465,MATCH($A36,'MATERIALS DB'!$A$4:$A$465,0)),"Code not found")) -> Rail 2.4 m | D36: =IF($A36="","",IFERROR(INDEX('MATERIALS DB'!$B$4:$B$465,MATCH($A36,'MATERIALS DB'!$A$4:$A$465,0)),"")) -> Mounting | E36: =IF($A36="","",IFERROR(INDEX('MATERIALS DB'!$C$4:$C$465,MATCH($A36,'MATERIALS DB'!$A$4:$A$465,0)),"")) -> Blue Carbon | F36: =IF($A36="","",IFERROR(INDEX('MATERIALS DB'!$F$4:$F$465,MATCH($A36,'MATERIALS DB'!$A$4:$A$465,0)),"")) -> pc | G36: =IF($A36="",0,IFERROR(INDEX('MATERIALS DB'!$W$4:$W$465,MATCH($A36,'MATERIALS DB'!$A$4:$A$465,0)),0)) -> 555.2988 | H36: =IF($A36="",0,IFERROR(INDEX('MATERIALS DB'!$Y$4:$Y$465,MATCH($A36,'MATERIALS DB'!$A$4:$A$465,0)),0)) -> 0.3 | I36: =B36*G36 -> 4442.3904 | J36: =I36*H36 -> 1332.7171 | K36: =I36+J36 -> 5775.1075 | L36: =IF($A36="",0,IFERROR(B36*INDEX('MATERIALS DB'!$Q$4:$Q$465,MATCH($A36,'MATERIALS DB'!$A$4:$A$465,0))*(INDEX(SUPPLIERS!$F$3:$F$30,MATCH(E36,SUPPLIERS!$A$3:$A$30,0))<>"Yes"),0)) -> 0.0069333333 | M36: =IF($A36="",0,IFERROR(INDEX('MATERIALS DB'!$N$4:$N$465,MATCH($A36,'MATERIALS DB'!$A$4:$A$465,0)),0)) -> 2.6 | O36: =IF(N36="","",N36-I36) | Q36: =IF($A36="",0,IFERROR(INDEX('MATERIALS DB'!$K$4:$K$465,MATCH($A36,'MATERIALS DB'!$A$4:$A$465,0)),0)) -> 0 | R36: =IF($A36="",0,IF(OR(D36="All-in-one System",AND(D36="Inverter",OR(ISNUMBER(SEARCH("hybrid",C36)),ISNUMBER(SEARCH("off-grid",C36))))),1,0)) -> 0
A37: BC-MNT-006 | B37: 24 | C37: =IF($A37="","",IFERROR(INDEX('MATERIALS DB'!$D$4:$D$465,MATCH($A37,'MATERIALS DB'!$A$4:$A$465,0)),"Code not found")) -> L-leg (L-foot) | D37: =IF($A37="","",IFERROR(INDEX('MATERIALS DB'!$B$4:$B$465,MATCH($A37,'MATERIALS DB'!$A$4:$A$465,0)),"")) -> Mounting | E37: =IF($A37="","",IFERROR(INDEX('MATERIALS DB'!$C$4:$C$465,MATCH($A37,'MATERIALS DB'!$A$4:$A$465,0)),"")) -> Blue Carbon | F37: =IF($A37="","",IFERROR(INDEX('MATERIALS DB'!$F$4:$F$465,MATCH($A37,'MATERIALS DB'!$A$4:$A$465,0)),"")) -> pc | G37: =IF($A37="",0,IFERROR(INDEX('MATERIALS DB'!$W$4:$W$465,MATCH($A37,'MATERIALS DB'!$A$4:$A$465,0)),0)) -> 71.659546 | H37: =IF($A37="",0,IFERROR(INDEX('MATERIALS DB'!$Y$4:$Y$465,MATCH($A37,'MATERIALS DB'!$A$4:$A$465,0)),0)) -> 0.3 | I37: =B37*G37 -> 1719.8291 | J37: =I37*H37 -> 515.94873 | K37: =I37+J37 -> 2235.7778 | L37: =IF($A37="",0,IFERROR(B37*INDEX('MATERIALS DB'!$Q$4:$Q$465,MATCH($A37,'MATERIALS DB'!$A$4:$A$465,0))*(INDEX(SUPPLIERS!$F$3:$F$30,MATCH(E37,SUPPLIERS!$A$3:$A$30,0))<>"Yes"),0)) -> 0.0012 | M37: =IF($A37="",0,IFERROR(INDEX('MATERIALS DB'!$N$4:$N$465,MATCH($A37,'MATERIALS DB'!$A$4:$A$465,0)),0)) -> 0.15 | O37: =IF(N37="","",N37-I37) | Q37: =IF($A37="",0,IFERROR(INDEX('MATERIALS DB'!$K$4:$K$465,MATCH($A37,'MATERIALS DB'!$A$4:$A$465,0)),0)) -> 0 | R37: =IF($A37="",0,IF(OR(D37="All-in-one System",AND(D37="Inverter",OR(ISNUMBER(SEARCH("hybrid",C37)),ISNUMBER(SEARCH("off-grid",C37))))),1,0)) -> 0
A38: BC-MNT-003 | B38: 8 | C38: =IF($A38="","",IFERROR(INDEX('MATERIALS DB'!$D$4:$D$465,MATCH($A38,'MATERIALS DB'!$A$4:$A$465,0)),"Code not found")) -> End clamp | D38: =IF($A38="","",IFERROR(INDEX('MATERIALS DB'!$B$4:$B$465,MATCH($A38,'MATERIALS DB'!$A$4:$A$465,0)),"")) -> Mounting | E38: =IF($A38="","",IFERROR(INDEX('MATERIALS DB'!$C$4:$C$465,MATCH($A38,'MATERIALS DB'!$A$4:$A$465,0)),"")) -> Blue Carbon | F38: =IF($A38="","",IFERROR(INDEX('MATERIALS DB'!$F$4:$F$465,MATCH($A38,'MATERIALS DB'!$A$4:$A$465,0)),"")) -> pc | G38: =IF($A38="",0,IFERROR(INDEX('MATERIALS DB'!$W$4:$W$465,MATCH($A38,'MATERIALS DB'!$A$4:$A$465,0)),0)) -> 39.918425 | H38: =IF($A38="",0,IFERROR(INDEX('MATERIALS DB'!$Y$4:$Y$465,MATCH($A38,'MATERIALS DB'!$A$4:$A$465,0)),0)) -> 0.3 | I38: =B38*G38 -> 319.3474 | J38: =I38*H38 -> 95.804219 | K38: =I38+J38 -> 415.15162 | L38: =IF($A38="",0,IFERROR(B38*INDEX('MATERIALS DB'!$Q$4:$Q$465,MATCH($A38,'MATERIALS DB'!$A$4:$A$465,0))*(INDEX(SUPPLIERS!$F$3:$F$30,MATCH(E38,SUPPLIERS!$A$3:$A$30,0))<>"Yes"),0)) -> 0.00021333333 | M38: =IF($A38="",0,IFERROR(INDEX('MATERIALS DB'!$N$4:$N$465,MATCH($A38,'MATERIALS DB'!$A$4:$A$465,0)),0)) -> 0.08 | O38: =IF(N38="","",N38-I38) | Q38: =IF($A38="",0,IFERROR(INDEX('MATERIALS DB'!$K$4:$K$465,MATCH($A38,'MATERIALS DB'!$A$4:$A$465,0)),0)) -> 0 | R38: =IF($A38="",0,IF(OR(D38="All-in-one System",AND(D38="Inverter",OR(ISNUMBER(SEARCH("hybrid",C38)),ISNUMBER(SEARCH("off-grid",C38))))),1,0)) -> 0
A39: BC-MNT-004 | B39: 12 | C39: =IF($A39="","",IFERROR(INDEX('MATERIALS DB'!$D$4:$D$465,MATCH($A39,'MATERIALS DB'!$A$4:$A$465,0)),"Code not found")) -> Mid clamp | D39: =IF($A39="","",IFERROR(INDEX('MATERIALS DB'!$B$4:$B$465,MATCH($A39,'MATERIALS DB'!$A$4:$A$465,0)),"")) -> Mounting | E39: =IF($A39="","",IFERROR(INDEX('MATERIALS DB'!$C$4:$C$465,MATCH($A39,'MATERIALS DB'!$A$4:$A$465,0)),"")) -> Blue Carbon | F39: =IF($A39="","",IFERROR(INDEX('MATERIALS DB'!$F$4:$F$465,MATCH($A39,'MATERIALS DB'!$A$4:$A$465,0)),"")) -> pc | G39: =IF($A39="",0,IFERROR(INDEX('MATERIALS DB'!$W$4:$W$465,MATCH($A39,'MATERIALS DB'!$A$4:$A$465,0)),0)) -> 43.998425 | H39: =IF($A39="",0,IFERROR(INDEX('MATERIALS DB'!$Y$4:$Y$465,MATCH($A39,'MATERIALS DB'!$A$4:$A$465,0)),0)) -> 0.3 | I39: =B39*G39 -> 527.9811 | J39: =I39*H39 -> 158.39433 | K39: =I39+J39 -> 686.37543 | L39: =IF($A39="",0,IFERROR(B39*INDEX('MATERIALS DB'!$Q$4:$Q$465,MATCH($A39,'MATERIALS DB'!$A$4:$A$465,0))*(INDEX(SUPPLIERS!$F$3:$F$30,MATCH(E39,SUPPLIERS!$A$3:$A$30,0))<>"Yes"),0)) -> 0.00032 | M39: =IF($A39="",0,IFERROR(INDEX('MATERIALS DB'!$N$4:$N$465,MATCH($A39,'MATERIALS DB'!$A$4:$A$465,0)),0)) -> 0.08 | O39: =IF(N39="","",N39-I39) | Q39: =IF($A39="",0,IFERROR(INDEX('MATERIALS DB'!$K$4:$K$465,MATCH($A39,'MATERIALS DB'!$A$4:$A$465,0)),0)) -> 0 | R39: =IF($A39="",0,IF(OR(D39="All-in-one System",AND(D39="Inverter",OR(ISNUMBER(SEARCH("hybrid",C39)),ISNUMBER(SEARCH("off-grid",C39))))),1,0)) -> 0
A40: BC-MNT-005 | B40: 4 | C40: =IF($A40="","",IFERROR(INDEX('MATERIALS DB'!$D$4:$D$465,MATCH($A40,'MATERIALS DB'!$A$4:$A$465,0)),"Code not found")) -> Rail splice | D40: =IF($A40="","",IFERROR(INDEX('MATERIALS DB'!$B$4:$B$465,MATCH($A40,'MATERIALS DB'!$A$4:$A$465,0)),"")) -> Mounting | E40: =IF($A40="","",IFERROR(INDEX('MATERIALS DB'!$C$4:$C$465,MATCH($A40,'MATERIALS DB'!$A$4:$A$465,0)),"")) -> Blue Carbon | F40: =IF($A40="","",IFERROR(INDEX('MATERIALS DB'!$F$4:$F$465,MATCH($A40,'MATERIALS DB'!$A$4:$A$465,0)),"")) -> pc | G40: =IF($A40="",0,IFERROR(INDEX('MATERIALS DB'!$W$4:$W$465,MATCH($A40,'MATERIALS DB'!$A$4:$A$465,0)),0)) -> 61.459546 | H40: =IF($A40="",0,IFERROR(INDEX('MATERIALS DB'!$Y$4:$Y$465,MATCH($A40,'MATERIALS DB'!$A$4:$A$465,0)),0)) -> 0.3 | I40: =B40*G40 -> 245.83819 | J40: =I40*H40 -> 73.751456 | K40: =I40+J40 -> 319.58964 | L40: =IF($A40="",0,IFERROR(B40*INDEX('MATERIALS DB'!$Q$4:$Q$465,MATCH($A40,'MATERIALS DB'!$A$4:$A$465,0))*(INDEX(SUPPLIERS!$F$3:$F$30,MATCH(E40,SUPPLIERS!$A$3:$A$30,0))<>"Yes"),0)) -> 0.0002 | M40: =IF($A40="",0,IFERROR(INDEX('MATERIALS DB'!$N$4:$N$465,MATCH($A40,'MATERIALS DB'!$A$4:$A$465,0)),0)) -> 0.15 | O40: =IF(N40="","",N40-I40) | Q40: =IF($A40="",0,IFERROR(INDEX('MATERIALS DB'!$K$4:$K$465,MATCH($A40,'MATERIALS DB'!$A$4:$A$465,0)),0)) -> 0 | R40: =IF($A40="",0,IF(OR(D40="All-in-one System",AND(D40="Inverter",OR(ISNUMBER(SEARCH("hybrid",C40)),ISNUMBER(SEARCH("off-grid",C40))))),1,0)) -> 0
A41: BC-WIR-001 | B41: 15 | C41: =IF($A41="","",IFERROR(INDEX('MATERIALS DB'!$D$4:$D$465,MATCH($A41,'MATERIALS DB'!$A$4:$A$465,0)),"Code not found")) -> Solar cable 4mm2, red | D41: =IF($A41="","",IFERROR(INDEX('MATERIALS DB'!$B$4:$B$465,MATCH($A41,'MATERIALS DB'!$A$4:$A$465,0)),"")) -> Wires and Terminations | E41: =IF($A41="","",IFERROR(INDEX('MATERIALS DB'!$C$4:$C$465,MATCH($A41,'MATERIALS DB'!$A$4:$A$465,0)),"")) -> Blue Carbon | F41: =IF($A41="","",IFERROR(INDEX('MATERIALS DB'!$F$4:$F$465,MATCH($A41,'MATERIALS DB'!$A$4:$A$465,0)),"")) -> m | G41: =IF($A41="",0,IFERROR(INDEX('MATERIALS DB'!$W$4:$W$465,MATCH($A41,'MATERIALS DB'!$A$4:$A$465,0)),0)) -> 48.920167 | H41: =IF($A41="",0,IFERROR(INDEX('MATERIALS DB'!$Y$4:$Y$465,MATCH($A41,'MATERIALS DB'!$A$4:$A$465,0)),0)) -> 0.3 | I41: =B41*G41 -> 733.8025 | J41: =I41*H41 -> 220.14075 | K41: =I41+J41 -> 953.94326 | L41: =IF($A41="",0,IFERROR(B41*INDEX('MATERIALS DB'!$Q$4:$Q$465,MATCH($A41,'MATERIALS DB'!$A$4:$A$465,0))*(INDEX(SUPPLIERS!$F$3:$F$30,MATCH(E41,SUPPLIERS!$A$3:$A$30,0))<>"Yes"),0)) -> 0.000275 | M41: =IF($A41="",0,IFERROR(INDEX('MATERIALS DB'!$N$4:$N$465,MATCH($A41,'MATERIALS DB'!$A$4:$A$465,0)),0)) -> 0.055 | O41: =IF(N41="","",N41-I41) | Q41: =IF($A41="",0,IFERROR(INDEX('MATERIALS DB'!$K$4:$K$465,MATCH($A41,'MATERIALS DB'!$A$4:$A$465,0)),0)) -> 0 | R41: =IF($A41="",0,IF(OR(D41="All-in-one System",AND(D41="Inverter",OR(ISNUMBER(SEARCH("hybrid",C41)),ISNUMBER(SEARCH("off-grid",C41))))),1,0)) -> 0
A42: BC-WIR-002 | B42: 15 | C42: =IF($A42="","",IFERROR(INDEX('MATERIALS DB'!$D$4:$D$465,MATCH($A42,'MATERIALS DB'!$A$4:$A$465,0)),"Code not found")) -> Solar cable 4mm2, black | D42: =IF($A42="","",IFERROR(INDEX('MATERIALS DB'!$B$4:$B$465,MATCH($A42,'MATERIALS DB'!$A$4:$A$465,0)),"")) -> Wires and Terminations | E42: =IF($A42="","",IFERROR(INDEX('MATERIALS DB'!$C$4:$C$465,MATCH($A42,'MATERIALS DB'!$A$4:$A$465,0)),"")) -> Blue Carbon | F42: =IF($A42="","",IFERROR(INDEX('MATERIALS DB'!$F$4:$F$465,MATCH($A42,'MATERIALS DB'!$A$4:$A$465,0)),"")) -> m | G42: =IF($A42="",0,IFERROR(INDEX('MATERIALS DB'!$W$4:$W$465,MATCH($A42,'MATERIALS DB'!$A$4:$A$465,0)),0)) -> 48.920167 | H42: =IF($A42="",0,IFERROR(INDEX('MATERIALS DB'!$Y$4:$Y$465,MATCH($A42,'MATERIALS DB'!$A$4:$A$465,0)),0)) -> 0.3 | I42: =B42*G42 -> 733.8025 | J42: =I42*H42 -> 220.14075 | K42: =I42+J42 -> 953.94326 | L42: =IF($A42="",0,IFERROR(B42*INDEX('MATERIALS DB'!$Q$4:$Q$465,MATCH($A42,'MATERIALS DB'!$A$4:$A$465,0))*(INDEX(SUPPLIERS!$F$3:$F$30,MATCH(E42,SUPPLIERS!$A$3:$A$30,0))<>"Yes"),0)) -> 0.000275 | M42: =IF($A42="",0,IFERROR(INDEX('MATERIALS DB'!$N$4:$N$465,MATCH($A42,'MATERIALS DB'!$A$4:$A$465,0)),0)) -> 0.055 | O42: =IF(N42="","",N42-I42) | Q42: =IF($A42="",0,IFERROR(INDEX('MATERIALS DB'!$K$4:$K$465,MATCH($A42,'MATERIALS DB'!$A$4:$A$465,0)),0)) -> 0 | R42: =IF($A42="",0,IF(OR(D42="All-in-one System",AND(D42="Inverter",OR(ISNUMBER(SEARCH("hybrid",C42)),ISNUMBER(SEARCH("off-grid",C42))))),1,0)) -> 0
A43: IAN-WIR-004 | B43: 35 | C43: =IF($A43="","",IFERROR(INDEX('MATERIALS DB'!$D$4:$D$465,MATCH($A43,'MATERIALS DB'!$A$4:$A$465,0)),"Code not found")) -> THHN 8.0mm2 EURO WIRES | D43: =IF($A43="","",IFERROR(INDEX('MATERIALS DB'!$B$4:$B$465,MATCH($A43,'MATERIALS DB'!$A$4:$A$465,0)),"")) -> Wires and Terminations | E43: =IF($A43="","",IFERROR(INDEX('MATERIALS DB'!$C$4:$C$465,MATCH($A43,'MATERIALS DB'!$A$4:$A$465,0)),"")) -> IAN Solar | F43: =IF($A43="","",IFERROR(INDEX('MATERIALS DB'!$F$4:$F$465,MATCH($A43,'MATERIALS DB'!$A$4:$A$465,0)),"")) -> m | G43: =IF($A43="",0,IFERROR(INDEX('MATERIALS DB'!$W$4:$W$465,MATCH($A43,'MATERIALS DB'!$A$4:$A$465,0)),0)) -> 94.678222 | H43: =IF($A43="",0,IFERROR(INDEX('MATERIALS DB'!$Y$4:$Y$465,MATCH($A43,'MATERIALS DB'!$A$4:$A$465,0)),0)) -> 0.3 | I43: =B43*G43 -> 3313.7378 | J43: =I43*H43 -> 994.12133 | K43: =I43+J43 -> 4307.8591 | L43: =IF($A43="",0,IFERROR(B43*INDEX('MATERIALS DB'!$Q$4:$Q$465,MATCH($A43,'MATERIALS DB'!$A$4:$A$465,0))*(INDEX(SUPPLIERS!$F$3:$F$30,MATCH(E43,SUPPLIERS!$A$3:$A$30,0))<>"Yes"),0)) -> 0.0012016667 | M43: =IF($A43="",0,IFERROR(INDEX('MATERIALS DB'!$N$4:$N$465,MATCH($A43,'MATERIALS DB'!$A$4:$A$465,0)),0)) -> 0.103 | O43: =IF(N43="","",N43-I43) | Q43: =IF($A43="",0,IFERROR(INDEX('MATERIALS DB'!$K$4:$K$465,MATCH($A43,'MATERIALS DB'!$A$4:$A$465,0)),0)) -> 0 | R43: =IF($A43="",0,IF(OR(D43="All-in-one System",AND(D43="Inverter",OR(ISNUMBER(SEARCH("hybrid",C43)),ISNUMBER(SEARCH("off-grid",C43))))),1,0)) -> 0
...

Sheet MATERIALS DB
A1: MATERIALS DB - landed cost per unit before freight, and selling price. Freight is one line per job. Sorted by category, then supplier
A3: Code | B3: Category (input) | C3: Supplier (input) | D3: Item | E3: Model / spec | F3: Unit | G3: Sold as | H3: List price, VAT-ex (input) | I3: Dealer discount | J3: Net price | K3: Rating (input) | L3: Rating unit | M3: Net price per rating unit | N3: Package weight kg (input) | O3: Package volume m3 (input) | P3: Weight/volume source | Q3: Truck share per unit | R3: Units per full truck | S3: Handling | T3: Wastage | U3: Payment fee | V3: Storage (input) | W3: LANDED COST before freight | X3: Landed over net price | Y3: Markup tier | Z3: Selling price (before freight, commission, VAT) | AA3: Customer price (with 5% commission, VAT; freight not included) | AB3: Price list date | AC3: Previous price (Sep 7) | AD3: Remarks
A4: BC-PNL-001 | B4: Solar Panel | C4: Blue Carbon | D4: 585W Monofacial solar panel | E4: BCT-585M10NH-144, TOPCon, 2278x1134x30 mm | F4: pc | G4: pc | H4: 4950 | I4: =INDEX(SUPPLIERS!$D$3:$D$30,MATCH(C4,SUPPLIERS!$A$3:$A$30,0)) -> 0 | J4: =H4*(1-I4) -> 4950 | K4: 585 | L4: W | M4: =IF(K4="","",J4/K4) -> 8.4615385 | N4: 26 | O4: 0.08525 | P4: Datasheet (volume +10% packing) | Q4: =MAX(N4/DRIVERS!$B$5,O4/DRIVERS!$B$6) -> 0.0086666667 | R4: =ROUNDDOWN(1/Q4,0) -> 115 | S4: =DRIVERS!$B$23*Q4/DRIVERS!$B$24 -> 44.988024 | T4: =J4*INDEX(DRIVERS!$C$32:$C$42,MATCH(B4,DRIVERS!$A$32:$A$42,0)) -> 0 | U4: =J4*INDEX(SUPPLIERS!$E$3:$E$30,MATCH(C4,SUPPLIERS!$A$3:$A$30,0)) -> 0 | V4: 0 | W4: =J4+S4+T4+U4+V4 -> 4994.988 | X4: =W4/J4-1 -> 0.0090884897 | Y4: =INDEX(DRIVERS!$B$32:$B$42,MATCH(B4,DRIVERS!$A$32:$A$42,0)) -> 0.1 | Z4: =W4*(1+Y4) -> 5494.4868 | AA4: =W4*(1+Y4+DRIVERS!$B$26)*(1+DRIVERS!$B$27) -> 6433.5446 | AB4: Sep 19, 2026 | AC4: 4950 | AD4: Price list model code BCT-16M-144-585W
A5: BC-PNL-002 | B5: Solar Panel | C5: Blue Carbon | D5: 585W Bifacial solar panel | E5: BCT-585M10NHB-144, TOPCon, 2278x1134x30 mm | F5: pc | G5: pc | H5: 4980 | I5: =INDEX(SUPPLIERS!$D$3:$D$30,MATCH(C5,SUPPLIERS!$A$3:$A$30,0)) -> 0 | J5: =H5*(1-I5) -> 4980 | K5: 585 | L5: W | M5: =IF(K5="","",J5/K5) -> 8.5128205 | N5: 30.2 | O5: 0.08525 | P5: Datasheet (volume +10% packing) | Q5: =MAX(N5/DRIVERS!$B$5,O5/DRIVERS!$B$6) -> 0.010066667 | R5: =ROUNDDOWN(1/Q5,0) -> 99 | S5: =DRIVERS!$B$23*Q5/DRIVERS!$B$24 -> 52.25532 | T5: =J5*INDEX(DRIVERS!$C$32:$C$42,MATCH(B5,DRIVERS!$A$32:$A$42,0)) -> 0 | U5: =J5*INDEX(SUPPLIERS!$E$3:$E$30,MATCH(C5,SUPPLIERS!$A$3:$A$30,0)) -> 0 | V5: 0 | W5: =J5+S5+T5+U5+V5 -> 5032.2553 | X5: =W5/J5-1 -> 0.010493036 | Y5: =INDEX(DRIVERS!$B$32:$B$42,MATCH(B5,DRIVERS!$A$32:$A$42,0)) -> 0.1 | Z5: =W5*(1+Y5) -> 5535.4809 | AA5: =W5*(1+Y5+DRIVERS!$B$26)*(1+DRIVERS!$B$27) -> 6481.5449 | AB5: Sep 19, 2026 | AC5: 4980
A6: BC-PNL-003 | B6: Solar Panel | C6: Blue Carbon | D6: 600W Monofacial solar panel | E6: BCT-600G12RNH-132, TOPCon, 2382x1134x30 mm | F6: pc | G6: pc | H6: 4999 | I6: =INDEX(SUPPLIERS!$D$3:$D$30,MATCH(C6,SUPPLIERS!$A$3:$A$30,0)) -> 0 | J6: =H6*(1-I6) -> 4999 | K6: 600 | L6: W | M6: =IF(K6="","",J6/K6) -> 8.3316667 | N6: 27.7 | O6: 0.08914 | P6: Datasheet (volume +10% packing) | Q6: =MAX(N6/DRIVERS!$B$5,O6/DRIVERS!$B$6) -> 0.0092333333 | R6: =ROUNDDOWN(1/Q6,0) -> 108 | S6: =DRIVERS!$B$23*Q6/DRIVERS!$B$24 -> 47.929548 | T6: =J6*INDEX(DRIVERS!$C$32:$C$42,MATCH(B6,DRIVERS!$A$32:$A$42,0)) -> 0 | U6: =J6*INDEX(SUPPLIERS!$E$3:$E$30,MATCH(C6,SUPPLIERS!$A$3:$A$30,0)) -> 0 | V6: 0 | W6: =J6+S6+T6+U6+V6 -> 5046.9295 | X6: =W6/J6-1 -> 0.0095878273 | Y6: =INDEX(DRIVERS!$B$32:$B$42,MATCH(B6,DRIVERS!$A$32:$A$42,0)) -> 0.1 | Z6: =W6*(1+Y6) -> 5551.6225 | AA6: =W6*(1+Y6+DRIVERS!$B$26)*(1+DRIVERS!$B$27) -> 6500.4453 | AB6: Sep 19, 2026 | AC6: 4999 | AD6: CHECK: the Sep 7 list gives model BCT-G12RNHB-132-600, which is the bifacial code (32.0 kg). Confirm mono or bifacial
A7: BC-PNL-004 | B7: Solar Panel | C7: Blue Carbon | D7: 630W Bifacial solar panel | E7: Datasheet received: BCT-630G12RNH-132 (monofacial), 2382x1134x30 mm | F7: pc | G7: pc | H7: 5450 | I7: =INDEX(SUPPLIERS!$D$3:$D$30,MATCH(C7,SUPPLIERS!$A$3:$A$30,0)) -> 0 | J7: =H7*(1-I7) -> 5450 | K7: 630 | L7: W | M7: =IF(K7="","",J7/K7) -> 8.6507937 | N7: 27.7 | O7: 0.08914 | P7: Datasheet (volume +10% packing) | Q7: =MAX(N7/DRIVERS!$B$5,O7/DRIVERS!$B$6) -> 0.0092333333 | R7: =ROUNDDOWN(1/Q7,0) -> 108 | S7: =DRIVERS!$B$23*Q7/DRIVERS!$B$24 -> 47.929548 | T7: =J7*INDEX(DRIVERS!$C$32:$C$42,MATCH(B7,DRIVERS!$A$32:$A$42,0)) -> 0 | U7: =J7*INDEX(SUPPLIERS!$E$3:$E$30,MATCH(C7,SUPPLIERS!$A$3:$A$30,0)) -> 0 | V7: 0 | W7: =J7+S7+T7+U7+V7 -> 5497.9295 | X7: =W7/J7-1 -> 0.0087944126 | Y7: =INDEX(DRIVERS!$B$32:$B$42,MATCH(B7,DRIVERS!$A$32:$A$42,0)) -> 0.1 | Z7: =W7*(1+Y7) -> 6047.7225 | AA7: =W7*(1+Y7+DRIVERS!$B$26)*(1+DRIVERS!$B$27) -> 7081.3333 | AB7: Sep 19, 2026 | AD7: CHECK: price list says bifacial, datasheet is monofacial. A bifacial 630 W would weigh about 32 kg. New on the Sep 19 list
A8: IAN-PNL-001 | B8: Solar Panel | C8: IAN Solar | D8: JA JAM66D46 720W N-TYPE BIFACIAL | E8: JA Solar; 720 W; N-type; bifacial; Luzon branch price; large-format panel | F8: pc | G8: pc | H8: 6750 | I8: =INDEX(SUPPLIERS!$D$3:$D$30,MATCH(C8,SUPPLIERS!$A$3:$A$30,0)) -> 0 | J8: =H8*(1-I8) -> 6750 | K8: 720 | L8: W | M8: =IF(K8="","",J8/K8) -> 9.375 | N8: 38.2 | O8: 0.11276 | P8: List panel weight; volume = panel size +10% (list packaging is per pallet) | Q8: =MAX(N8/DRIVERS!$B$5,O8/DRIVERS!$B$6) -> 0.012733333 | R8: =ROUNDDOWN(1/Q8,0) -> 78 | S8: =DRIVERS!$B$23*Q8/DRIVERS!$B$24 -> 66.097789 | T8: =J8*INDEX(DRIVERS!$C$32:$C$42,MATCH(B8,DRIVERS!$A$32:$A$42,0)) -> 0 | U8: =J8*INDEX(SUPPLIERS!$E$3:$E$30,MATCH(C8,SUPPLIERS!$A$3:$A$30,0)) -> 0 | V8: 0 | W8: =J8+S8+T8+U8+V8 -> 6816.0978 | X8: =W8/J8-1 -> 0.009792265 | Y8: =INDEX(DRIVERS!$B$32:$B$42,MATCH(B8,DRIVERS!$A$32:$A$42,0)) -> 0.1 | Z8: =W8*(1+Y8) -> 7497.7076 | AA8: =W8*(1+Y8+DRIVERS!$B$26)*(1+DRIVERS!$B$27) -> 8779.134 | AB8: Sep 3, 2026
A9: IAN-PNL-002 | B9: Solar Panel | C9: IAN Solar | D9: IAN670-132BCDGF 670W N-TYPE BIFACIAL BC | E9: IAN Solar; 670 W; N-type; bifacial; back-contact; Luzon branch price | F9: pc | G9: pc | H9: 6400 | I9: =INDEX(SUPPLIERS!$D$3:$D$30,MATCH(C9,SUPPLIERS!$A$3:$A$30,0)) -> 0 | J9: =H9*(1-I9) -> 6400 | K9: 670 | L9: W | M9: =IF(K9="","",J9/K9) -> 9.5522388 | N9: 32.5 | O9: 0.08914 | P9: List panel weight; volume = panel size +10% (list packaging is per pallet) | Q9: =MAX(N9/DRIVERS!$B$5,O9/DRIVERS!$B$6) -> 0.010833333 | R9: =ROUNDDOWN(1/Q9,0) -> 92 | S9: =DRIVERS!$B$23*Q9/DRIVERS!$B$24 -> 56.23503 | T9: =J9*INDEX(DRIVERS!$C$32:$C$42,MATCH(B9,DRIVERS!$A$32:$A$42,0)) -> 0 | U9: =J9*INDEX(SUPPLIERS!$E$3:$E$30,MATCH(C9,SUPPLIERS!$A$3:$A$30,0)) -> 0 | V9: 0 | W9: =J9+S9+T9+U9+V9 -> 6456.235 | X9: =W9/J9-1 -> 0.0087867234 | Y9: =INDEX(DRIVERS!$B$32:$B$42,MATCH(B9,DRIVERS!$A$32:$A$42,0)) -> 0.1 | Z9: =W9*(1+Y9) -> 7101.8585 | AA9: =W9*(1+Y9+DRIVERS!$B$26)*(1+DRIVERS!$B$27) -> 8315.6307 | AB9: Sep 3, 2026
A10: IAN-PNL-003 | B10: Solar Panel | C10: IAN Solar | D10: JA JAM66D45 625W N-TYPE BIFACIAL | E10: JA Solar; 625 W; N-type; bifacial; Luzon branch price | F10: pc | G10: pc | H10: 6150 | I10: =INDEX(SUPPLIERS!$D$3:$D$30,MATCH(C10,SUPPLIERS!$A$3:$A$30,0)) -> 0 | J10: =H10*(1-I10) -> 6150 | K10: 625 | L10: W | M10: =IF(K10="","",J10/K10) -> 9.84 | N10: 33.1 | O10: 0.08914 | P10: List panel weight; volume = panel size +10% (list packaging is per pallet) | Q10: =MAX(N10/DRIVERS!$B$5,O10/DRIVERS!$B$6) -> 0.011033333 | R10: =ROUNDDOWN(1/Q10,0) -> 90 | S10: =DRIVERS!$B$23*Q10/DRIVERS!$B$24 -> 57.273215 | T10: =J10*INDEX(DRIVERS!$C$32:$C$42,MATCH(B10,DRIVERS!$A$32:$A$42,0)) -> 0 | U10: =J10*INDEX(SUPPLIERS!$E$3:$E$30,MATCH(C10,SUPPLIERS!$A$3:$A$30,0)) -> 0 | V10: 0 | W10: =J10+S10+T10+U10+V10 -> 6207.2732 | X10: =W10/J10-1 -> 0.0093127179 | Y10: =INDEX(DRIVERS!$B$32:$B$42,MATCH(B10,DRIVERS!$A$32:$A$42,0)) -> 0.1 | Z10: =W10*(1+Y10) -> 6828.0005 | AA10: =W10*(1+Y10+DRIVERS!$B$26)*(1+DRIVERS!$B$27) -> 7994.9679 | AB10: Sep 3, 2026
A11: IAN-PNL-004 | B11: Solar Panel | C11: IAN Solar | D11: JA JAM66D45 630W N-TYPE BIFACIAL | E11: JA Solar; 630 W; N-type; bifacial; Luzon branch price | F11: pc | G11: pc | H11: 6250 | I11: =INDEX(SUPPLIERS!$D$3:$D$30,MATCH(C11,SUPPLIERS!$A$3:$A$30,0)) -> 0 | J11: =H11*(1-I11) -> 6250 | K11: 630 | L11: W | M11: =IF(K11="","",J11/K11) -> 9.9206349 | N11: 33.1 | O11: 0.08914 | P11: List panel weight; volume = panel size +10% (list packaging is per pallet) | Q11: =MAX(N11/DRIVERS!$B$5,O11/DRIVERS!$B$6) -> 0.011033333 | R11: =ROUNDDOWN(1/Q11,0) -> 90 | S11: =DRIVERS!$B$23*Q11/DRIVERS!$B$24 -> 57.273215 | T11: =J11*INDEX(DRIVERS!$C$32:$C$42,MATCH(B11,DRIVERS!$A$32:$A$42,0)) -> 0 | U11: =J11*INDEX(SUPPLIERS!$E$3:$E$30,MATCH(C11,SUPPLIERS!$A$3:$A$30,0)) -> 0 | V11: 0 | W11: =J11+S11+T11+U11+V11 -> 6307.2732 | X11: =W11/J11-1 -> 0.0091637144 | Y11: =INDEX(DRIVERS!$B$32:$B$42,MATCH(B11,DRIVERS!$A$32:$A$42,0)) -> 0.1 | Z11: =W11*(1+Y11) -> 6938.0005 | AA11: =W11*(1+Y11+DRIVERS!$B$26)*(1+DRIVERS!$B$27) -> 8123.7679 | AB11: Sep 3, 2026
A12: OP-PNL-001 | B12: Solar Panel | C12: One Point | D12: 200W 10BB MONO | E12: Solar Homes; 200 W; Solar Homes | F12: pc | G12: pc | H12: 3000 | I12: =INDEX(SUPPLIERS!$D$3:$D$30,MATCH(C12,SUPPLIERS!$A$3:$A$30,0)) -> 0 | J12: =H12*(1-I12) -> 3000 | K12: 200 | L12: W | M12: =IF(K12="","",J12/K12) -> 15 | N12: 14 | O12: 0.04884 | P12: List panel weight; volume = panel size +10% (list packaging is per pallet) | Q12: =MAX(N12/DRIVERS!$B$5,O12/DRIVERS!$B$6) -> 0.0046666667 | R12: =ROUNDDOWN(1/Q12,0) -> 214 | S12: =DRIVERS!$B$23*Q12/DRIVERS!$B$24 -> 24.224321 | T12: =J12*INDEX(DRIVERS!$C$32:$C$42,MATCH(B12,DRIVERS!$A$32:$A$42,0)) -> 0 | U12: =J12*INDEX(SUPPLIERS!$E$3:$E$30,MATCH(C12,SUPPLIERS!$A$3:$A$30,0)) -> 0 | V12: 0 | W12: =J12+S12+T12+U12+V12 -> 3024.2243 | X12: =W12/J12-1 -> 0.0080747735 | Y12: =INDEX(DRIVERS!$B$32:$B$42,MATCH(B12,DRIVERS!$A$32:$A$42,0)) -> 0.1 | Z12: =W12*(1+Y12) -> 3326.6468 | AA12: =W12*(1+Y12+DRIVERS!$B$26)*(1+DRIVERS!$B$27) -> 3895.2009 | AB12: Sep 11, 2026
A13: OP-PNL-002 | B13: Solar Panel | C13: One Point | D13: 150W 10BB MONO | E13: Solar Homes; 150 W; Solar Homes | F13: pc | G13: pc | H13: 2500 | I13: =INDEX(SUPPLIERS!$D$3:$D$30,MATCH(C13,SUPPLIERS!$A$3:$A$30,0)) -> 0 | J13: =H13*(1-I13) -> 2500 | K13: 150 | L13: W | M13: =IF(K13="","",J13/K13) -> 16.666667 | N13: 9.5 | O13: 0.02638 | P13: List panel weight; volume = panel size +10% (list packaging is per pallet) | Q13: =MAX(N13/DRIVERS!$B$5,O13/DRIVERS!$B$6) -> 0.0031666667 | R13: =ROUNDDOWN(1/Q13,0) -> 315 | S13: =DRIVERS!$B$23*Q13/DRIVERS!$B$24 -> 16.437932 | T13: =J13*INDEX(DRIVERS!$C$32:$C$42,MATCH(B13,DRIVERS!$A$32:$A$42,0)) -> 0 | U13: =J13*INDEX(SUPPLIERS!$E$3:$E$30,MATCH(C13,SUPPLIERS!$A$3:$A$30,0)) -> 0 | V13: 0 | W13: =J13+S13+T13+U13+V13 -> 2516.4379 | X13: =W13/J13-1 -> 0.0065751727 | Y13: =INDEX(DRIVERS!$B$32:$B$42,MATCH(B13,DRIVERS!$A$32:$A$42,0)) -> 0.1 | Z13: =W13*(1+Y13) -> 2768.0817 | AA13: =W13*(1+Y13+DRIVERS!$B$26)*(1+DRIVERS!$B$27) -> 3241.1721 | AB13: Sep 11, 2026
A14: OP-PNL-003 | B14: Solar Panel | C14: One Point | D14: 100W 10BB MONO | E14: Solar Homes; 100 W; Solar Homes | F14: pc | G14: pc | H14: 2000 | I14: =INDEX(SUPPLIERS!$D$3:$D$30,MATCH(C14,SUPPLIERS!$A$3:$A$30,0)) -> 0 | J14: =H14*(1-I14) -> 2000 | K14: 100 | L14: W | M14: =IF(K14="","",J14/K14) -> 20 | N14: 7.8 | O14: 0.01806 | P14: List panel weight; volume = panel size +10% (list packaging is per pallet) | Q14: =MAX(N14/DRIVERS!$B$5,O14/DRIVERS!$B$6) -> 0.0026 | R14: =ROUNDDOWN(1/Q14,0) -> 384 | S14: =DRIVERS!$B$23*Q14/DRIVERS!$B$24 -> 13.496407 | T14: =J14*INDEX(DRIVERS!$C$32:$C$42,MATCH(B14,DRIVERS!$A$32:$A$42,0)) -> 0 | U14: =J14*INDEX(SUPPLIERS!$E$3:$E$30,MATCH(C14,SUPPLIERS!$A$3:$A$30,0)) -> 0 | V14: 0 | W14: =J14+S14+T14+U14+V14 -> 2013.4964 | X14: =W14/J14-1 -> 0.0067482036 | Y14: =INDEX(DRIVERS!$B$32:$B$42,MATCH(B14,DRIVERS!$A$32:$A$42,0)) -> 0.1 | Z14: =W14*(1+Y14) -> 2214.846 | AA14: =W14*(1+Y14+DRIVERS!$B$26)*(1+DRIVERS!$B$27) -> 2593.3834 | AB14: Sep 11, 2026
A15: OP-PNL-004 | B15: Solar Panel | C15: One Point | D15: TRINA-MONO-620W - N TYPE | E15: Trina Solar; 620 W; N-type | F15: pc | G15: pc | H15: 5900 | I15: =INDEX(SUPPLIERS!$D$3:$D$30,MATCH(C15,SUPPLIERS!$A$3:$A$30,0)) -> 0 | J15: =H15*(1-I15) -> 5900 | K15: 620 | L15: W | M15: =IF(K15="","",J15/K15) -> 9.516129 | N15: 27.9 | O15: 0.08914 | P15: List panel weight; volume = panel size +10% (list packaging is per pallet) | Q15: =MAX(N15/DRIVERS!$B$5,O15/DRIVERS!$B$6) -> 0.0093 | R15: =ROUNDDOWN(1/Q15,0) -> 107 | S15: =DRIVERS!$B$23*Q15/DRIVERS!$B$24 -> 48.27561 | T15: =J15*INDEX(DRIVERS!$C$32:$C$42,MATCH(B15,DRIVERS!$A$32:$A$42,0)) -> 0 | U15: =J15*INDEX(SUPPLIERS!$E$3:$E$30,MATCH(C15,SUPPLIERS!$A$3:$A$30,0)) -> 0 | V15: 0 | W15: =J15+S15+T15+U15+V15 -> 5948.2756 | X15: =W15/J15-1 -> 0.0081823068 | Y15: =INDEX(DRIVERS!$B$32:$B$42,MATCH(B15,DRIVERS!$A$32:$A$42,0)) -> 0.1 | Z15: =W15*(1+Y15) -> 6543.1032 | AA15: =W15*(1+Y15+DRIVERS!$B$26)*(1+DRIVERS!$B$27) -> 7661.379 | AB15: Sep 11, 2026
A16: OP-PNL-005 | B16: Solar Panel | C16: One Point | D16: TRINA-MONO-630W - N TYPE | E16: Trina Solar; 630 W; N-type | F16: pc | G16: pc | H16: 6000 | I16: =INDEX(SUPPLIERS!$D$3:$D$30,MATCH(C16,SUPPLIERS!$A$3:$A$30,0)) -> 0 | J16: =H16*(1-I16) -> 6000 | K16: 630 | L16: W | M16: =IF(K16="","",J16/K16) -> 9.5238095 | N16: 27.9 | O16: 0.08914 | P16: List panel weight; volume = panel size +10% (list packaging is per pallet) | Q16: =MAX(N16/DRIVERS!$B$5,O16/DRIVERS!$B$6) -> 0.0093 | R16: =ROUNDDOWN(1/Q16,0) -> 107 | S16: =DRIVERS!$B$23*Q16/DRIVERS!$B$24 -> 48.27561 | T16: =J16*INDEX(DRIVERS!$C$32:$C$42,MATCH(B16,DRIVERS!$A$32:$A$42,0)) -> 0 | U16: =J16*INDEX(SUPPLIERS!$E$3:$E$30,MATCH(C16,SUPPLIERS!$A$3:$A$30,0)) -> 0 | V16: 0 | W16: =J16+S16+T16+U16+V16 -> 6048.2756 | X16: =W16/J16-1 -> 0.008045935 | Y16: =INDEX(DRIVERS!$B$32:$B$42,MATCH(B16,DRIVERS!$A$32:$A$42,0)) -> 0.1 | Z16: =W16*(1+Y16) -> 6653.1032 | AA16: =W16*(1+Y16+DRIVERS!$B$26)*(1+DRIVERS!$B$27) -> 7790.179 | AB16: Sep 11, 2026
A17: OP-PNL-006 | B17: Solar Panel | C17: One Point | D17: AIKO ABC - 665W BI-FACIAL | E17: Aiko; 665 W; bifacial; back-contact | F17: pc | G17: pc | H17: 6600 | I17: =INDEX(SUPPLIERS!$D$3:$D$30,MATCH(C17,SUPPLIERS!$A$3:$A$30,0)) -> 0 | J17: =H17*(1-I17) -> 6600 | K17: 665 | L17: W | M17: =IF(K17="","",J17/K17) -> 9.924812 | N17: 32.5 | O17: 0.08914 | P17: List panel weight; volume = panel size +10% (list packaging is per pallet) | Q17: =MAX(N17/DRIVERS!$B$5,O17/DRIVERS!$B$6) -> 0.010833333 | R17: =ROUNDDOWN(1/Q17,0) -> 92 | S17: =DRIVERS!$B$23*Q17/DRIVERS!$B$24 -> 56.23503 | T17: =J17*INDEX(DRIVERS!$C$32:$C$42,MATCH(B17,DRIVERS!$A$32:$A$42,0)) -> 0 | U17: =J17*INDEX(SUPPLIERS!$E$3:$E$30,MATCH(C17,SUPPLIERS!$A$3:$A$30,0)) -> 0 | V17: 0 | W17: =J17+S17+T17+U17+V17 -> 6656.235 | X17: =W17/J17-1 -> 0.0085204591 | Y17: =INDEX(DRIVERS!$B$32:$B$42,MATCH(B17,DRIVERS!$A$32:$A$42,0)) -> 0.1 | Z17: =W17*(1+Y17) -> 7321.8585 | AA17: =W17*(1+Y17+DRIVERS!$B$26)*(1+DRIVERS!$B$27) -> 8573.2307 | AB17: Sep 11, 2026
A18: BC-INV-001 | B18: Inverter | C18: Blue Carbon | D18: 4 kW 24V hybrid off-grid inverter, single use | E18: BCT-FXC-4KW | F18: pc | G18: pc | H18: 12600 | I18: =INDEX(SUPPLIERS!$D$3:$D$30,MATCH(C18,SUPPLIERS!$A$3:$A$30,0)) -> 0 | J18: =H18*(1-I18) -> 12600 | K18: 4 | L18: kW | M18: =IF(K18="","",J18/K18) -> 3150 | N18: 8 | O18: 0.045 | P18: Est. | Q18: =MAX(N18/DRIVERS!$B$5,O18/DRIVERS!$B$6) -> 0.0031525535 | R18: =ROUNDDOWN(1/Q18,0) -> 317 | S18: =DRIVERS!$B$23*Q18/DRIVERS!$B$24 -> 16.364671 | T18: =J18*INDEX(DRIVERS!$C$32:$C$42,MATCH(B18,DRIVERS!$A$32:$A$42,0)) -> 0 | U18: =J18*INDEX(SUPPLIERS!$E$3:$E$30,MATCH(C18,SUPPLIERS!$A$3:$A$30,0)) -> 0 | V18: 0 | W18: =J18+S18+T18+U18+V18 -> 12616.365 | X18: =W18/J18-1 -> 0.0012987834 | Y18: =INDEX(DRIVERS!$B$32:$B$42,MATCH(B18,DRIVERS!$A$32:$A$42,0)) -> 0.1 | Z18: =W18*(1+Y18) -> 13878.001 | AA18: =W18*(1+Y18+DRIVERS!$B$26)*(1+DRIVERS!$B$27) -> 16249.878 | AB18: Sep 19, 2026 | AC18: 12600 | AD18: Off-grid type
A19: BC-INV-002 | B19: Inverter | C19: Blue Carbon | D19: 6 kW 48V hybrid off-grid inverter, single use | E19: BCT-FXC-6KW | F19: pc | G19: pc | H19: 16200 | I19: =INDEX(SUPPLIERS!$D$3:$D$30,MATCH(C19,SUPPLIERS!$A$3:$A$30,0)) -> 0 | J19: =H19*(1-I19) -> 16200 | K19: 6 | L19: kW | M19: =IF(K19="","",J19/K19) -> 2700 | N19: 9 | O19: 0.048 | P19: Weight: -P datasheet; volume Est. | Q19: =MAX(N19/DRIVERS!$B$5,O19/DRIVERS!$B$6) -> 0.0033627237 | R19: =ROUNDDOWN(1/Q19,0) -> 297 | S19: =DRIVERS!$B$23*Q19/DRIVERS!$B$24 -> 17.455649 | T19: =J19*INDEX(DRIVERS!$C$32:$C$42,MATCH(B19,DRIVERS!$A$32:$A$42,0)) -> 0 | U19: =J19*INDEX(SUPPLIERS!$E$3:$E$30,MATCH(C19,SUPPLIERS!$A$3:$A$30,0)) -> 0 | V19: 0 | W19: =J19+S19+T19+U19+V19 -> 16217.456 | X19: =W19/J19-1 -> 0.0010775092 | Y19: =INDEX(DRIVERS!$B$32:$B$42,MATCH(B19,DRIVERS!$A$32:$A$42,0)) -> 0.1 | Z19: =W19*(1+Y19) -> 17839.201 | AA19: =W19*(1+Y19+DRIVERS!$B$26)*(1+DRIVERS!$B$27) -> 20888.083 | AB19: Sep 19, 2026 | AC19: 16200 | AD19: Off-grid type
A20: BC-INV-003 | B20: Inverter | C20: Blue Carbon | D20: 6 kW 48V hybrid off-grid inverter, parallel | E20: BCT-FXC-6KW-P, 510x306x115 mm | F20: pc | G20: pc | H20: 17400 | I20: =INDEX(SUPPLIERS!$D$3:$D$30,MATCH(C20,SUPPLIERS!$A$3:$A$30,0)) -> 0 | J20: =H20*(1-I20) -> 17400 | K20: 6 | L20: kW | M20: =IF(K20="","",J20/K20) -> 2900 | N20: 9 | O20: 0.048 | P20: Weight: datasheet; volume Est. | Q20: =MAX(N20/DRIVERS!$B$5,O20/DRIVERS!$B$6) -> 0.0033627237 | R20: =ROUNDDOWN(1/Q20,0) -> 297 | S20: =DRIVERS!$B$23*Q20/DRIVERS!$B$24 -> 17.455649 | T20: =J20*INDEX(DRIVERS!$C$32:$C$42,MATCH(B20,DRIVERS!$A$32:$A$42,0)) -> 0 | U20: =J20*INDEX(SUPPLIERS!$E$3:$E$30,MATCH(C20,SUPPLIERS!$A$3:$A$30,0)) -> 0 | V20: 0 | W20: =J20+S20+T20+U20+V20 -> 17417.456 | X20: =W20/J20-1 -> 0.0010031982 | Y20: =INDEX(DRIVERS!$B$32:$B$42,MATCH(B20,DRIVERS!$A$32:$A$42,0)) -> 0.1 | Z20: =W20*(1+Y20) -> 19159.201 | AA20: =W20*(1+Y20+DRIVERS!$B$26)*(1+DRIVERS!$B$27) -> 22433.683 | AB20: Sep 19, 2026 | AC20: 17400 | AD20: Off-grid type with feed-in; PV max 18A / 6,000 W, 500 Voc. CHECK grid-tie certification before any net-metered job
A21: BC-INV-004 | B21: Inverter | C21: Blue Carbon | D21: 6.5 kW 48V hybrid off-grid inverter, parallel | E21: BCT-FXC-6.5KW-P | F21: pc | G21: pc | H21: 20500 | I21: =INDEX(SUPPLIERS!$D$3:$D$30,MATCH(C21,SUPPLIERS!$A$3:$A$30,0)) -> 0 | J21: =H21*(1-I21) -> 20500 | K21: 6.5 | L21: kW | M21: =IF(K21="","",J21/K21) -> 3153.8462 | N21: 10 | O21: 0.05 | P21: Est. (datasheet not received) | Q21: =MAX(N21/DRIVERS!$B$5,O21/DRIVERS!$B$6) -> 0.0035028372 | R21: =ROUNDDOWN(1/Q21,0) -> 285 | S21: =DRIVERS!$B$23*Q21/DRIVERS!$B$24 -> 18.182968 | T21: =J21*INDEX(DRIVERS!$C$32:$C$42,MATCH(B21,DRIVERS!$A$32:$A$42,0)) -> 0 | U21: =J21*INDEX(SUPPLIERS!$E$3:$E$30,MATCH(C21,SUPPLIERS!$A$3:$A$30,0)) -> 0 | V21: 0 | W21: =J21+S21+T21+U21+V21 -> 20518.183 | X21: =W21/J21-1 -> 0.00088697405 | Y21: =INDEX(DRIVERS!$B$32:$B$42,MATCH(B21,DRIVERS!$A$32:$A$42,0)) -> 0.1 | Z21: =W21*(1+Y21) -> 22570.001 | AA21: =W21*(1+Y21+DRIVERS!$B$26)*(1+DRIVERS!$B$27) -> 26427.42 | AB21: Sep 19, 2026 | AC21: 20500 | AD21: Off-grid type
A22: BC-INV-005 | B22: Inverter | C22: Blue Carbon | D22: 6.5 kW 48V hybrid off-grid inverter, parallel (H) | E22: BCT-FXC-6.5KW-P-H | F22: pc | G22: pc | H22: 22000 | I22: =INDEX(SUPPLIERS!$D$3:$D$30,MATCH(C22,SUPPLIERS!$A$3:$A$30,0)) -> 0 | J22: =H22*(1-I22) -> 22000 | K22: 6.5 | L22: kW | M22: =IF(K22="","",J22/K22) -> 3384.6154 | N22: 10 | O22: 0.05 | P22: Est. | Q22: =MAX(N22/DRIVERS!$B$5,O22/DRIVERS!$B$6) -> 0.0035028372 | R22: =ROUNDDOWN(1/Q22,0) -> 285 | S22: =DRIVERS!$B$23*Q22/DRIVERS!$B$24 -> 18.182968 | T22: =J22*INDEX(DRIVERS!$C$32:$C$42,MATCH(B22,DRIVERS!$A$32:$A$42,0)) -> 0 | U22: =J22*INDEX(SUPPLIERS!$E$3:$E$30,MATCH(C22,SUPPLIERS!$A$3:$A$30,0)) -> 0 | V22: 0 | W22: =J22+S22+T22+U22+V22 -> 22018.183 | X22: =W22/J22-1 -> 0.00082649854 | Y22: =INDEX(DRIVERS!$B$32:$B$42,MATCH(B22,DRIVERS!$A$32:$A$42,0)) -> 0.1 | Z22: =W22*(1+Y22) -> 24220.001 | AA22: =W22*(1+Y22+DRIVERS!$B$26)*(1+DRIVERS!$B$27) -> 28359.42 | AB22: Sep 19, 2026 | AC22: 22000 | AD22: Off-grid type
A23: BC-INV-006 | B23: Inverter | C23: Blue Carbon | D23: 8 kW hybrid inverter (on/off-grid) | E23: BCT-DLL-L1M3-8KW | F23: pc | G23: pc | H23: 63500 | I23: =INDEX(SUPPLIERS!$D$3:$D$30,MATCH(C23,SUPPLIERS!$A$3:$A$30,0)) -> 0 | J23: =H23*(1-I23) -> 63500 | K23: 8 | L23: kW | M23: =IF(K23="","",J23/K23) -> 7937.5 | N23: 35.6 | O23: 0.12 | P23: Est. (same cabinet as 10/12 kW assumed) | Q23: =MAX(N23/DRIVERS!$B$5,O23/DRIVERS!$B$6) -> 0.011866667 | R23: =ROUNDDOWN(1/Q23,0) -> 84 | S23: =DRIVERS!$B$23*Q23/DRIVERS!$B$24 -> 61.598986 | T23: =J23*INDEX(DRIVERS!$C$32:$C$42,MATCH(B23,DRIVERS!$A$32:$A$42,0)) -> 0 | U23: =J23*INDEX(SUPPLIERS!$E$3:$E$30,MATCH(C23,SUPPLIERS!$A$3:$A$30,0)) -> 0 | V23: 0 | W23: =J23+S23+T23+U23+V23 -> 63561.599 | X23: =W23/J23-1 -> 0.00097006278 | Y23: =INDEX(DRIVERS!$B$32:$B$42,MATCH(B23,DRIVERS!$A$32:$A$42,0)) -> 0.1 | Z23: =W23*(1+Y23) -> 69917.759 | AA23: =W23*(1+Y23+DRIVERS!$B$26)*(1+DRIVERS!$B$27) -> 81867.339 | AB23: Sep 19, 2026 | AC23: 65000
A24: BC-INV-007 | B24: Inverter | C24: Blue Carbon | D24: 10 kW hybrid inverter (on/off-grid) | E24: BCT-DLL-L1M3-10KW, 420x670x233 mm | F24: pc | G24: pc | H24: 79000 | I24: =INDEX(SUPPLIERS!$D$3:$D$30,MATCH(C24,SUPPLIERS!$A$3:$A$30,0)) -> 0 | J24: =H24*(1-I24) -> 79000 | K24: 10 | L24: kW | M24: =IF(K24="","",J24/K24) -> 7900 | N24: 35.6 | O24: 0.12 | P24: Weight: datasheet; volume Est. | Q24: =MAX(N24/DRIVERS!$B$5,O24/DRIVERS!$B$6) -> 0.011866667 | R24: =ROUNDDOWN(1/Q24,0) -> 84 | S24: =DRIVERS!$B$23*Q24/DRIVERS!$B$24 -> 61.598986 | T24: =J24*INDEX(DRIVERS!$C$32:$C$42,MATCH(B24,DRIVERS!$A$32:$A$42,0)) -> 0 | U24: =J24*INDEX(SUPPLIERS!$E$3:$E$30,MATCH(C24,SUPPLIERS!$A$3:$A$30,0)) -> 0 | V24: 0 | W24: =J24+S24+T24+U24+V24 -> 79061.599 | X24: =W24/J24-1 -> 0.00077973401 | Y24: =INDEX(DRIVERS!$B$32:$B$42,MATCH(B24,DRIVERS!$A$32:$A$42,0)) -> 0.1 | Z24: =W24*(1+Y24) -> 86967.759 | AA24: =W24*(1+Y24+DRIVERS!$B$26)*(1+DRIVERS!$B$27) -> 101831.34 | AB24: Sep 19, 2026 | AC24: 90000 | AD24: 3 MPPT at 26A each; battery 220A; 16 units parallel; 5-yr warranty
A25: BC-INV-008 | B25: Inverter | C25: Blue Carbon | D25: 12 kW hybrid inverter (on/off-grid) | E25: BCT-DLL-L1M3-12KW, 420x670x233 mm | F25: pc | G25: pc | H25: 89000 | I25: =INDEX(SUPPLIERS!$D$3:$D$30,MATCH(C25,SUPPLIERS!$A$3:$A$30,0)) -> 0 | J25: =H25*(1-I25) -> 89000 | K25: 12 | L25: kW | M25: =IF(K25="","",J25/K25) -> 7416.6667 | N25: 35.6 | O25: 0.12 | P25: Weight: datasheet; volume Est. | Q25: =MAX(N25/DRIVERS!$B$5,O25/DRIVERS!$B$6) -> 0.011866667 | R25: =ROUNDDOWN(1/Q25,0) -> 84 | S25: =DRIVERS!$B$23*Q25/DRIVERS!$B$24 -> 61.598986 | T25: =J25*INDEX(DRIVERS!$C$32:$C$42,MATCH(B25,DRIVERS!$A$32:$A$42,0)) -> 0 | U25: =J25*INDEX(SUPPLIERS!$E$3:$E$30,MATCH(C25,SUPPLIERS!$A$3:$A$30,0)) -> 0 | V25: 0 | W25: =J25+S25+T25+U25+V25 -> 89061.599 | X25: =W25/J25-1 -> 0.00069212344 | Y25: =INDEX(DRIVERS!$B$32:$B$42,MATCH(B25,DRIVERS!$A$32:$A$42,0)) -> 0.1 | Z25: =W25*(1+Y25) -> 97967.759 | AA25: =W25*(1+Y25+DRIVERS!$B$26)*(1+DRIVERS!$B$27) -> 114711.34 | AB25: Sep 19, 2026 | AC25: 95000 | AD25: 3 MPPT at 26A each; battery 250A; 5-yr warranty
A26: FS-INV-001 | B26: Inverter | C26: Felicity Solar | D26: 6 kW low-voltage hybrid inverter (grid-tie + backup) | E26: IVGM6KLP1G2, 470x376x251 mm | F26: pc | G26: pc | H26: 43000 | I26: =INDEX(SUPPLIERS!$D$3:$D$30,MATCH(C26,SUPPLIERS!$A$3:$A$30,0)) -> 0 | J26: =H26*(1-I26) -> 43000 | K26: 6 | L26: kW | M26: =IF(K26="","",J26/K26) -> 7166.6667 | N26: 24.5 | O26: 0.09448 | P26: Brochure: gross weight, package | Q26: =MAX(N26/DRIVERS!$B$5,O26/DRIVERS!$B$6) -> 0.0081666667 | R26: =ROUNDDOWN(1/Q26,0) -> 122 | S26: =DRIVERS!$B$23*Q26/DRIVERS!$B$24 -> 42.392561 | T26: =J26*INDEX(DRIVERS!$C$32:$C$42,MATCH(B26,DRIVERS!$A$32:$A$42,0)) -> 0 | U26: =J26*INDEX(SUPPLIERS!$E$3:$E$30,MATCH(C26,SUPPLIERS!$A$3:$A$30,0)) -> 0 | V26: 0 | W26: =J26+S26+T26+U26+V26 -> 43042.393 | X26: =W26/J26-1 -> 0.00098587351 | Y26: =INDEX(DRIVERS!$B$32:$B$42,MATCH(B26,DRIVERS!$A$32:$A$42,0)) -> 0.1 | Z26: =W26*(1+Y26) -> 47346.632 | AA26: =W26*(1+Y26+DRIVERS!$B$26)*(1+DRIVERS!$B$27) -> 55438.602 | AB26: September 2026 | AD26: 2 MPPT, 18A each (27A short-circuit); battery 135A; IEC 61727 / 62116 listed; 10-yr warranty. Same price as the 6 kW inverter in the packages
A27: FS-INV-002 | B27: Inverter | C27: Felicity Solar | D27: 8 kW low-voltage hybrid inverter (grid-tie + backup) | E27: IVGM8KLP1G1, 430x654x243 mm | F27: pc | G27: pc | H27: 63000 | I27: =INDEX(SUPPLIERS!$D$3:$D$30,MATCH(C27,SUPPLIERS!$A$3:$A$30,0)) -> 0 | J27: =H27*(1-I27) -> 63000 | K27: 8 | L27: kW | M27: =IF(K27="","",J27/K27) -> 7875 | N27: 40.5 | O27: 0.15412 | P27: Brochure: gross weight, package | Q27: =MAX(N27/DRIVERS!$B$5,O27/DRIVERS!$B$6) -> 0.0135 | R27: =ROUNDDOWN(1/Q27,0) -> 74 | S27: =DRIVERS!$B$23*Q27/DRIVERS!$B$24 -> 70.077499 | T27: =J27*INDEX(DRIVERS!$C$32:$C$42,MATCH(B27,DRIVERS!$A$32:$A$42,0)) -> 0 | U27: =J27*INDEX(SUPPLIERS!$E$3:$E$30,MATCH(C27,SUPPLIERS!$A$3:$A$30,0)) -> 0 | V27: 0 | W27: =J27+S27+T27+U27+V27 -> 63070.077 | X27: =W27/J27-1 -> 0.0011123412 | Y27: =INDEX(DRIVERS!$B$32:$B$42,MATCH(B27,DRIVERS!$A$32:$A$42,0)) -> 0.1 | Z27: =W27*(1+Y27) -> 69377.085 | AA27: =W27*(1+Y27+DRIVERS!$B$26)*(1+DRIVERS!$B$27) -> 81234.26 | AB27: September 2026 | AD27: 2 MPPT, 26A each; battery 190A; 10-yr warranty. CHECK: grid certifications marked "in progress" and IEC 61727 / 62116 not listed - confirm before a net-metered job
A28: FS-INV-003 | B28: Inverter | C28: Felicity Solar | D28: 12 kW low-voltage hybrid inverter (grid-tie + backup) | E28: IVGM16KLP1G1 | F28: pc | G28: pc | H28: 102000 | I28: =INDEX(SUPPLIERS!$D$3:$D$30,MATCH(C28,SUPPLIERS!$A$3:$A$30,0)) -> 0 | J28: =H28*(1-I28) -> 102000 | K28: 12 | L28: kW | M28: =IF(K28="","",J28/K28) -> 8500 | N28: 40.5 | O28: 0.154 | P28: Est. (no spec in brochure; 8 kW used) | Q28: =MAX(N28/DRIVERS!$B$5,O28/DRIVERS!$B$6) -> 0.0135 | R28: =ROUNDDOWN(1/Q28,0) -> 74 | S28: =DRIVERS!$B$23*Q28/DRIVERS!$B$24 -> 70.077499 | T28: =J28*INDEX(DRIVERS!$C$32:$C$42,MATCH(B28,DRIVERS!$A$32:$A$42,0)) -> 0 | U28: =J28*INDEX(SUPPLIERS!$E$3:$E$30,MATCH(C28,SUPPLIERS!$A$3:$A$30,0)) -> 0 | V28: 0 | W28: =J28+S28+T28+U28+V28 -> 102070.08 | X28: =W28/J28-1 -> 0.0006870343 | Y28: =INDEX(DRIVERS!$B$32:$B$42,MATCH(B28,DRIVERS!$A$32:$A$42,0)) -> 0.1 | Z28: =W28*(1+Y28) -> 112277.09 | AA28: =W28*(1+Y28+DRIVERS!$B$26)*(1+DRIVERS!$B$27) -> 131466.26 | AB28: September 2026 | AD28: CHECK: model code says 16K, price list says 12 kW. No spec sheet received. 10-yr warranty
A29: FS-INV-004 | B29: Inverter | C29: Felicity Solar | D29: 50 kW high-voltage hybrid inverter, 3-phase | E29: IVGM50KHP3G1, 940x582x340 mm | F29: pc | G29: pc | H29: 216000 | I29: =INDEX(SUPPLIERS!$D$3:$D$30,MATCH(C29,SUPPLIERS!$A$3:$A$30,0)) -> 0 | J29: =H29*(1-I29) -> 216000 | K29: 50 | L29: kW | M29: =IF(K29="","",J29/K29) -> 4320 | N29: 107.1 | O29: 0.40439 | P29: Brochure: gross weight, package | Q29: =MAX(N29/DRIVERS!$B$5,O29/DRIVERS!$B$6) -> 0.0357 | R29: =ROUNDDOWN(1/Q29,0) -> 28 | S29: =DRIVERS!$B$23*Q29/DRIVERS!$B$24 -> 185.31605 | T29: =J29*INDEX(DRIVERS!$C$32:$C$42,MATCH(B29,DRIVERS!$A$32:$A$42,0)) -> 0 | U29: =J29*INDEX(SUPPLIERS!$E$3:$E$30,MATCH(C29,SUPPLIERS!$A$3:$A$30,0)) -> 0 | V29: 0 | W29: =J29+S29+T29+U29+V29 -> 216185.32 | X29: =W29/J29-1 -> 0.00085794469 | Y29: =INDEX(DRIVERS!$B$32:$B$42,MATCH(B29,DRIVERS!$A$32:$A$42,0)) -> 0.1 | Z29: =W29*(1+Y29) -> 237803.85 | AA29: =W29*(1+Y29+DRIVERS!$B$26)*(1+DRIVERS!$B$27) -> 278446.69 | AB29: September 2026 | AD29: Commercial, 3-phase, high-voltage battery. 10-yr warranty
A30: FS-INV-005 | B30: Inverter | C30: Felicity Solar | D30: 6 kW low-voltage off-grid inverter | E30: IVEM6048-II, 420x335x142 mm | F30: pc | G30: pc | H30: 19000 | I30: =INDEX(SUPPLIERS!$D$3:$D$30,MATCH(C30,SUPPLIERS!$A$3:$A$30,0)) -> 0 | J30: =H30*(1-I30) -> 19000 | K30: 6 | L30: kW | M30: =IF(K30="","",J30/K30) -> 3166.6667 | N30: 14.5 | O30: 0.04612 | P30: Brochure: package; gross weight Est. (net 12.5 kg) | Q30: =MAX(N30/DRIVERS!$B$5,O30/DRIVERS!$B$6) -> 0.0048333333 | R30: =ROUNDDOWN(1/Q30,0) -> 206 | S30: =DRIVERS!$B$23*Q30/DRIVERS!$B$24 -> 25.089475 | T30: =J30*INDEX(DRIVERS!$C$32:$C$42,MATCH(B30,DRIVERS!$A$32:$A$42,0)) -> 0 | U30: =J30*INDEX(SUPPLIERS!$E$3:$E$30,MATCH(C30,SUPPLIERS!$A$3:$A$30,0)) -> 0 | V30: 0 | W30: =J30+S30+T30+U30+V30 -> 19025.089 | X30: =W30/J30-1 -> 0.0013204987 | Y30: =INDEX(DRIVERS!$B$32:$B$42,MATCH(B30,DRIVERS!$A$32:$A$42,0)) -> 0.1 | Z30: =W30*(1+Y30) -> 20927.598 | AA30: =W30*(1+Y30+DRIVERS!$B$26)*(1+DRIVERS!$B$27) -> 24504.315 | AB30: September 2026 | AD30: Off-grid type, 1 MPPT 27A, 500 Voc. 2-yr warranty
A31: FS-INV-006 | B31: Inverter | C31: Felicity Solar | D31: 8 kW low-voltage off-grid inverter | E31: IVEM8048-II, 607x464x141 mm | F31: pc | G31: pc | H31: 32000 | I31: =INDEX(SUPPLIERS!$D$3:$D$30,MATCH(C31,SUPPLIERS!$A$3:$A$30,0)) -> 0 | J31: =H31*(1-I31) -> 32000 | K31: 8 | L31: kW | M31: =IF(K31="","",J31/K31) -> 4000 | N31: 26 | O31: 0.10733 | P31: Brochure: package; gross weight Est. (net 23.7 kg) | Q31: =MAX(N31/DRIVERS!$B$5,O31/DRIVERS!$B$6) -> 0.0086666667 | R31: =ROUNDDOWN(1/Q31,0) -> 115 | S31: =DRIVERS!$B$23*Q31/DRIVERS!$B$24 -> 44.988024 | T31: =J31*INDEX(DRIVERS!$C$32:$C$42,MATCH(B31,DRIVERS!$A$32:$A$42,0)) -> 0 | U31: =J31*INDEX(SUPPLIERS!$E$3:$E$30,MATCH(C31,SUPPLIERS!$A$3:$A$30,0)) -> 0 | V31: 0 | W31: =J31+S31+T31+U31+V31 -> 32044.988 | X31: =W31/J31-1 -> 0.0014058757 | Y31: =INDEX(DRIVERS!$B$32:$B$42,MATCH(B31,DRIVERS!$A$32:$A$42,0)) -> 0.1 | Z31: =W31*(1+Y31) -> 35249.487 | AA31: =W31*(1+Y31+DRIVERS!$B$26)*(1+DRIVERS!$B$27) -> 41273.945 | AB31: September 2026 | AD31: Off-grid type, 2 x 20A PV. 2-yr warranty
A32: FS-INV-007 | B32: Inverter | C32: Felicity Solar | D32: 12 kW low-voltage off-grid inverter | E32: IVEM12048(-II), 634x476x141 mm | F32: pc | G32: pc | H32: 39000 | I32: =INDEX(SUPPLIERS!$D$3:$D$30,MATCH(C32,SUPPLIERS!$A$3:$A$30,0)) -> 0 | J32: =H32*(1-I32) -> 39000 | K32: 12 | L32: kW | M32: =IF(K32="","",J32/K32) -> 3250 | N32: 29.5 | O32: 0.11126 | P32: Brochure: package; gross weight Est. (net 26.8 kg) | Q32: =MAX(N32/DRIVERS!$B$5,O32/DRIVERS!$B$6) -> 0.0098333333 | R32: =ROUNDDOWN(1/Q32,0) -> 101 | S32: =DRIVERS!$B$23*Q32/DRIVERS!$B$24 -> 51.044104 | T32: =J32*INDEX(DRIVERS!$C$32:$C$42,MATCH(B32,DRIVERS!$A$32:$A$42,0)) -> 0 | U32: =J32*INDEX(SUPPLIERS!$E$3:$E$30,MATCH(C32,SUPPLIERS!$A$3:$A$30,0)) -> 0 | V32: 0 | W32: =J32+S32+T32+U32+V32 -> 39051.044 | X32: =W32/J32-1 -> 0.0013088232 | Y32: =INDEX(DRIVERS!$B$32:$B$42,MATCH(B32,DRIVERS!$A$32:$A$42,0)) -> 0.1 | Z32: =W32*(1+Y32) -> 42956.149 | AA32: =W32*(1+Y32+DRIVERS!$B$26)*(1+DRIVERS!$B$27) -> 50297.745 | AB32: September 2026 | AD32: Off-grid type, 2 x 27A PV. 2-yr warranty. Price list says IVEM12048, brochure IVEM12048-II
A33: FS-INV-008 | B33: Inverter | C33: Felicity Solar | D33: 6 kW low-voltage eco-hybrid inverter | E33: IVAM6048P1G1, 435x320x183 mm | F33: pc | G33: pc | H33: 25000 | I33: =INDEX(SUPPLIERS!$D$3:$D$30,MATCH(C33,SUPPLIERS!$A$3:$A$30,0)) -> 0 | J33: =H33*(1-I33) -> 25000 | K33: 6 | L33: kW | M33: =IF(K33="","",J33/K33) -> 4166.6667 | N33: 15.5 | O33: 0.05918 | P33: Brochure: package; gross weight Est. (net 13.5 kg) | Q33: =MAX(N33/DRIVERS!$B$5,O33/DRIVERS!$B$6) -> 0.0051666667 | R33: =ROUNDDOWN(1/Q33,0) -> 193 | S33: =DRIVERS!$B$23*Q33/DRIVERS!$B$24 -> 26.819783 | T33: =J33*INDEX(DRIVERS!$C$32:$C$42,MATCH(B33,DRIVERS!$A$32:$A$42,0)) -> 0 | U33: =J33*INDEX(SUPPLIERS!$E$3:$E$30,MATCH(C33,SUPPLIERS!$A$3:$A$30,0)) -> 0 | V33: 0 | W33: =J33+S33+T33+U33+V33 -> 25026.82 | X33: =W33/J33-1 -> 0.0010727913 | Y33: =INDEX(DRIVERS!$B$32:$B$42,MATCH(B33,DRIVERS!$A$32:$A$42,0)) -> 0.1 | Z33: =W33*(1+Y33) -> 27529.502 | AA33: =W33*(1+Y33+DRIVERS!$B$26)*(1+DRIVERS!$B$27) -> 32234.544 | AB33: September 2026 | AD33: Off-grid high-frequency type, 2 MPPT 20A each, battery 135A. Brochure: pilot production, specs may change. 5-yr warranty
A34: IAN-INV-001 | B34: Inverter | C34: IAN Solar | D34: SOLIS S6-GR1P6K GRID-TIE 6kW | E34: Solis; 6 kW; Grid-tie 1P; -S = Bluetooth version | F34: pc | G34: pc | H34: 25600 | I34: =INDEX(SUPPLIERS!$D$3:$D$30,MATCH(C34,SUPPLIERS!$A$3:$A$30,0)) -> 0 | J34: =H34*(1-I34) -> 25600 | K34: 6 | L34: kW | M34: =IF(K34="","",J34/K34) -> 4266.6667 | N34: 15 | O34: 0.06929 | P34: List: gross weight, packaging size | Q34: =MAX(N34/DRIVERS!$B$5,O34/DRIVERS!$B$6) -> 0.005 | R34: =ROUNDDOWN(1/Q34,0) -> 200 | S34: =DRIVERS!$B$23*Q34/DRIVERS!$B$24 -> 25.954629 | T34: =J34*INDEX(DRIVERS!$C$32:$C$42,MATCH(B34,DRIVERS!$A$32:$A$42,0)) -> 0 | U34: =J34*INDEX(SUPPLIERS!$E$3:$E$30,MATCH(C34,SUPPLIERS!$A$3:$A$30,0)) -> 0 | V34: 0 | W34: =J34+S34+T34+U34+V34 -> 25625.955 | X34: =W34/J34-1 -> 0.0010138527 | Y34: =INDEX(DRIVERS!$B$32:$B$42,MATCH(B34,DRIVERS!$A$32:$A$42,0)) -> 0.1 | Z34: =W34*(1+Y34) -> 28188.55 | AA34: =W34*(1+Y34+DRIVERS!$B$26)*(1+DRIVERS!$B$27) -> 33006.23 | AB34: Sep 3, 2026
A35: IAN-INV-002 | B35: Inverter | C35: IAN Solar | D35: SOLIS S6-GR1P10K03-NV-ND GRID-TIE 10kW | E35: Solis; 10 kW; Grid-tie 1P | F35: pc | G35: pc | H35: 47000 | I35: =INDEX(SUPPLIERS!$D$3:$D$30,MATCH(C35,SUPPLIERS!$A$3:$A$30,0)) -> 0 | J35: =H35*(1-I35) -> 47000 | K35: 10 | L35: kW | M35: =IF(K35="","",J35/K35) -> 4700 | N35: 21.5 | O35: 0.08463 | P35: List: gross weight, packaging size | Q35: =MAX(N35/DRIVERS!$B$5,O35/DRIVERS!$B$6) -> 0.0071666667 | R35: =ROUNDDOWN(1/Q35,0) -> 139 | S35: =DRIVERS!$B$23*Q35/DRIVERS!$B$24 -> 37.201635 | T35: =J35*INDEX(DRIVERS!$C$32:$C$42,MATCH(B35,DRIVERS!$A$32:$A$42,0)) -> 0 | U35: =J35*INDEX(SUPPLIERS!$E$3:$E$30,MATCH(C35,SUPPLIERS!$A$3:$A$30,0)) -> 0 | V35: 0 | W35: =J35+S35+T35+U35+V35 -> 47037.202 | X35: =W35/J35-1 -> 0.00079152415 | Y35: =INDEX(DRIVERS!$B$32:$B$42,MATCH(B35,DRIVERS!$A$32:$A$42,0)) -> 0.1 | Z35: =W35*(1+Y35) -> 51740.922 | AA35: =W35*(1+Y35+DRIVERS!$B$26)*(1+DRIVERS!$B$27) -> 60583.916 | AB35: Sep 3, 2026
A36: IAN-INV-003 | B36: Inverter | C36: IAN Solar | D36: SOLIS S5-GR1P8K GRID-TIE 8kW | E36: Solis; 8 kW; Grid-tie 1P | F36: pc | G36: pc | H36: 40000 | I36: =INDEX(SUPPLIERS!$D$3:$D$30,MATCH(C36,SUPPLIERS!$A$3:$A$30,0)) -> 0 | J36: =H36*(1-I36) -> 40000 | K36: 8 | L36: kW | M36: =IF(K36="","",J36/K36) -> 5000 | N36: 21.5 | O36: 0.10234 | P36: List: gross weight, packaging size | Q36: =MAX(N36/DRIVERS!$B$5,O36/DRIVERS!$B$6) -> 0.0071696071 | R36: =ROUNDDOWN(1/Q36,0) -> 139 | S36: =DRIVERS!$B$23*Q36/DRIVERS!$B$24 -> 37.216899 | T36: =J36*INDEX(DRIVERS!$C$32:$C$42,MATCH(B36,DRIVERS!$A$32:$A$42,0)) -> 0 | U36: =J36*INDEX(SUPPLIERS!$E$3:$E$30,MATCH(C36,SUPPLIERS!$A$3:$A$30,0)) -> 0 | V36: 0 | W36: =J36+S36+T36+U36+V36 -> 40037.217 | X36: =W36/J36-1 -> 0.00093042247 | Y36: =INDEX(DRIVERS!$B$32:$B$42,MATCH(B36,DRIVERS!$A$32:$A$42,0)) -> 0.1 | Z36: =W36*(1+Y36) -> 44040.939 | AA36: =W36*(1+Y36+DRIVERS!$B$26)*(1+DRIVERS!$B$27) -> 51567.935 | AB36: Sep 3, 2026
A37: IAN-INV-004 | B37: Inverter | C37: IAN Solar | D37: SOLIS S6-GR1P5K GRID-TIE 5kW | E37: Solis; 5 kW; Grid-tie 1P | F37: pc | G37: pc | H37: 25600 | I37: =INDEX(SUPPLIERS!$D$3:$D$30,MATCH(C37,SUPPLIERS!$A$3:$A$30,0)) -> 0 | J37: =H37*(1-I37) -> 25600 | K37: 5 | L37: kW | M37: =IF(K37="","",J37/K37) -> 5120 | N37: 15 | O37: 0.06145 | P37: List: gross weight, packaging size | Q37: =MAX(N37/DRIVERS!$B$5,O37/DRIVERS!$B$6) -> 0.005 | R37: =ROUNDDOWN(1/Q37,0) -> 200 | S37: =DRIVERS!$B$23*Q37/DRIVERS!$B$24 -> 25.954629 | T37: =J37*INDEX(DRIVERS!$C$32:$C$42,MATCH(B37,DRIVERS!$A$32:$A$42,0)) -> 0 | U37: =J37*INDEX(SUPPLIERS!$E$3:$E$30,MATCH(C37,SUPPLIERS!$A$3:$A$30,0)) -> 0 | V37: 0 | W37: =J37+S37+T37+U37+V37 -> 25625.955 | X37: =W37/J37-1 -> 0.0010138527 | Y37: =INDEX(DRIVERS!$B$32:$B$42,MATCH(B37,DRIVERS!$A$32:$A$42,0)) -> 0.1 | Z37: =W37*(1+Y37) -> 28188.55 | AA37: =W37*(1+Y37+DRIVERS!$B$26)*(1+DRIVERS!$B$27) -> 33006.23 | AB37: Sep 3, 2026
A38: IAN-INV-005 | B38: Inverter | C38: IAN Solar | D38: SOLIS S6-GR1P3K GRID-TIE 3kW | E38: Solis; 3 kW; Grid-tie 1P | F38: pc | G38: pc | H38: 22000 | I38: =INDEX(SUPPLIERS!$D$3:$D$30,MATCH(C38,SUPPLIERS!$A$3:$A$30,0)) -> 0 | J38: =H38*(1-I38) -> 22000 | K38: 3 | L38: kW | M38: =IF(K38="","",J38/K38) -> 7333.3333 | N38: 9 | O38: 0.05383 | P38: List: gross weight, packaging size | Q38: =MAX(N38/DRIVERS!$B$5,O38/DRIVERS!$B$6) -> 0.0037711545 | R38: =ROUNDDOWN(1/Q38,0) -> 265 | S38: =DRIVERS!$B$23*Q38/DRIVERS!$B$24 -> 19.575783 | T38: =J38*INDEX(DRIVERS!$C$32:$C$42,MATCH(B38,DRIVERS!$A$32:$A$42,0)) -> 0 | U38: =J38*INDEX(SUPPLIERS!$E$3:$E$30,MATCH(C38,SUPPLIERS!$A$3:$A$30,0)) -> 0 | V38: 0 | W38: =J38+S38+T38+U38+V38 -> 22019.576 | X38: =W38/J38-1 -> 0.00088980833 | Y38: =INDEX(DRIVERS!$B$32:$B$42,MATCH(B38,DRIVERS!$A$32:$A$42,0)) -> 0.1 | Z38: =W38*(1+Y38) -> 24221.533 | AA38: =W38*(1+Y38+DRIVERS!$B$26)*(1+DRIVERS!$B$27) -> 28361.214 | AB38: Sep 3, 2026
A39: IAN-INV-006 | B39: Inverter | C39: IAN Solar | D39: SOLIS S6-GC3P200K07-ND GRID-TIE 200kW 480V | E39: Solis; 200 kW; 480V | F39: pc | G39: pc | H39: 290000 | I39: =INDEX(SUPPLIERS!$D$3:$D$30,MATCH(C39,SUPPLIERS!$A$3:$A$30,0)) -> 0 | J39: =H39*(1-I39) -> 290000 | K39: 200 | L39: kW | M39: =IF(K39="","",J39/K39) -> 1450 | N39: 120 | O39: 0.69575 | P39: List: gross weight, packaging size | Q39: =MAX(N39/DRIVERS!$B$5,O39/DRIVERS!$B$6) -> 0.048741979 | R39: =ROUNDDOWN(1/Q39,0) -> 20 | S39: =DRIVERS!$B$23*Q39/DRIVERS!$B$24 -> 253.016 | T39: =J39*INDEX(DRIVERS!$C$32:$C$42,MATCH(B39,DRIVERS!$A$32:$A$42,0)) -> 0 | U39: =J39*INDEX(SUPPLIERS!$E$3:$E$30,MATCH(C39,SUPPLIERS!$A$3:$A$30,0)) -> 0 | V39: 0 | W39: =J39+S39+T39+U39+V39 -> 290253.02 | X39: =W39/J39-1 -> 0.00087246896 | Y39: =INDEX(DRIVERS!$B$32:$B$42,MATCH(B39,DRIVERS!$A$32:$A$42,0)) -> 0.1 | Z39: =W39*(1+Y39) -> 319278.32 | AA39: =W39*(1+Y39+DRIVERS!$B$26)*(1+DRIVERS!$B$27) -> 373845.88 | AB39: Sep 3, 2026
A40: IAN-INV-007 | B40: Inverter | C40: IAN Solar | D40: SOLIS S6-GC3P150K07-NV GRID-TIE 3P 150kW 380-400V | E40: Solis; 150 kW; 380-400V | F40: pc | G40: pc | H40: 250000 | I40: =INDEX(SUPPLIERS!$D$3:$D$30,MATCH(C40,SUPPLIERS!$A$3:$A$30,0)) -> 0 | J40: =H40*(1-I40) -> 250000 | K40: 150 | L40: kW | M40: =IF(K40="","",J40/K40) -> 1666.6667 | N40: 120 | O40: 0.598 | P40: List: gross weight, packaging size | Q40: =MAX(N40/DRIVERS!$B$5,O40/DRIVERS!$B$6) -> 0.041893933 | R40: =ROUNDDOWN(1/Q40,0) -> 23 | S40: =DRIVERS!$B$23*Q40/DRIVERS!$B$24 -> 217.4683 | T40: =J40*INDEX(DRIVERS!$C$32:$C$42,MATCH(B40,DRIVERS!$A$32:$A$42,0)) -> 0 | U40: =J40*INDEX(SUPPLIERS!$E$3:$E$30,MATCH(C40,SUPPLIERS!$A$3:$A$30,0)) -> 0 | V40: 0 | W40: =J40+S40+T40+U40+V40 -> 250217.47 | X40: =W40/J40-1 -> 0.00086987319 | Y40: =INDEX(DRIVERS!$B$32:$B$42,MATCH(B40,DRIVERS!$A$32:$A$42,0)) -> 0.1 | Z40: =W40*(1+Y40) -> 275239.22 | AA40: =W40*(1+Y40+DRIVERS!$B$26)*(1+DRIVERS!$B$27) -> 322280.1 | AB40: Sep 3, 2026
A41: IAN-INV-008 | B41: Inverter | C41: IAN Solar | D41: SOLIS-110K-5G-PRO GRID-TIE 3P 110kW 380-400V | E41: Solis; 110 kW; 380-400V | F41: pc | G41: pc | H41: 217000 | I41: =INDEX(SUPPLIERS!$D$3:$D$30,MATCH(C41,SUPPLIERS!$A$3:$A$30,0)) -> 0 | J41: =H41*(1-I41) -> 217000 | K41: 110 | L41: kW | M41: =IF(K41="","",J41/K41) -> 1972.7273 | N41: 100 | O41: 0.288 | P41: List: gross weight, packaging size | Q41: =MAX(N41/DRIVERS!$B$5,O41/DRIVERS!$B$6) -> 0.033333333 | R41: =ROUNDDOWN(1/Q41,0) -> 30 | S41: =DRIVERS!$B$23*Q41/DRIVERS!$B$24 -> 173.03086 | T41: =J41*INDEX(DRIVERS!$C$32:$C$42,MATCH(B41,DRIVERS!$A$32:$A$42,0)) -> 0 | U41: =J41*INDEX(SUPPLIERS!$E$3:$E$30,MATCH(C41,SUPPLIERS!$A$3:$A$30,0)) -> 0 | V41: 0 | W41: =J41+S41+T41+U41+V41 -> 217173.03 | X41: =W41/J41-1 -> 0.00079737724 | Y41: =INDEX(DRIVERS!$B$32:$B$42,MATCH(B41,DRIVERS!$A$32:$A$42,0)) -> 0.1 | Z41: =W41*(1+Y41) -> 238890.33 | AA41: =W41*(1+Y41+DRIVERS!$B$26)*(1+DRIVERS!$B$27) -> 279718.86 | AB41: Sep 3, 2026
...

Sheet NOTES
A1: PL Development Inc. - Materials database
A2: Suppliers: Blue Carbon (Sep 19, 2026 distributor list), Felicity Solar (September 2026 list), One Point (Sep 11, 2026 Main QC list, picked up at the Alabang branch; listed as One Solar on the canvass sheet) and IAN Solar (Sep 3, 2026 list). One Point and IAN Solar sizes and weights come from the earlier canvass sheet. All four are pickup only.
A4: Landed cost = your six groups (freight is added once per job; the other five are per item)
A5: 1 Base price - supplier list price, VAT-exclusive, less any dealer discount you enter in SUPPLIERS. Take the VAT invoice (12% more): PL Dev is VAT-registered, so that 12% comes back as input VAT against the output VAT on the customer invoice. Net cost = VAT-exclusive price. Without the invoice the purchase cannot be deducted for income tax.
